Workbook

Sheet Cover
B1: Version | C1: Status | D1: Date | E1: Author | F1: Comments
B2: v1 | C2: Old | D2: 46129 | E2: Laura Hargrave | F2: First draft for comment
B3: v2 | C3: Old | D3: 46141 | E3: Alf Pendlebury | F3: Added data owner & data source to relevant tabs
B4: v3 | C4: Old | D4: 46141 | E4: Laura Hargrave | F4: Added Governance Checkpoints tab & associated info
B5: v4 | C5: Current | D5: 46150 | E5: Alf Pendlebury | F5: Added Roles & Responsibilities tab & asscociated info. Finalised latest data updates to project tabs. Proj data now accurate as at 08/05/26.
B7: Notes:
B8: N1:

Sheet 📋 Instructions
A1: PURPOSE
B2: This register is the single source of truth for all active nxzen UK project data. It is completed weekly by Project Managers and Client Partners, then processed by the Portfolio Office to generate the Friday Portfolio Review dashboard.
A3: WHO COMPLETES WHAT
A4: Project Managers | B4: Complete the '🗂 Project Register', '🚦 Weekly Status Update', and '⚠️ Risks & Issues' tabs for each of your projects.
A5: Client Partners | B5: Complete the '💼 Commercial' tab for each of your accounts.
A6: Resource Manager | B6: Complete the '👥 Resource & Utilisation' tab each week.
A7: Finance | B7: Complete the '🗂 Project Register' columns XXX
A8: Portfolio Office | B8: Validate all inputs, track governance checkpoints in '✅ Gov Checkpoints' tab, run the report / automation, and distribute the dashboard by Friday PM.
A9: WEEKLY RHYTHM
A10: Thursday EOD | B10: PMs complete the '🗂 Project Register', '🚦 Weekly Status Update', and '⚠️ Risks & Issues' tabs for project ahead of their respecitve weekly elivery review call (Mon- Thurs).
A11: Friday AM | B11: Portfolio Office runs AI (Claude) automation and generates dashboard.
A12: Friday PM | B12: Dashboard distributed to Mohamed Syedian ahead of Tuesday SLT. PO saves a copy end of week for reference
A13: IMPORTANT RULES
A14: 1. Do NOT change column headers or tab names. | B14: The automation reads specific cell locations. Changing structure will break the dashboard.
A15: 2. Use the dropdowns provided. | B15: RAG status, Phase, Practice, and other fields have validated dropdowns. Do not type freehand.
A16: 3. Every active project must have a row. | B16: If a project is new, add a row in the Project Register first before updating status.
A17: 4. Never delete rows — mark as Closed instead. | B17: Set Status = 'Closed' in the Project Register to remove from active dashboard view.
A18: 5. Red RAG must have a comment. | B18: Any Red rating in the Weekly Status Update requires a comment in the 'Key Flag / Comment' column.
A19: 6. RAG Criteria | B19: xxx

Sheet Roles & Responsibilities
B1: Project Register Tab
B2: Responsible to populate | C2: Ref | D2: Project Name | E2: Client | F2: Sub-Prop / Practice | G2: Current Phase | H2: Status | I2: Start Date | J2: End Date (Baseline) | K2: End Date (Forecast) | L2: Days Slippage | M2: Contract Value (£) | N2: Margin Target (%) | O2: PM Name | P2: CP Name | Q2: Project Code | R2: Notes
B3: Portfolio Office | C3: TRUE | D3: TRUE | E3: TRUE | F3: TRUE | I3: TRUE | J3: TRUE | O3: TRUE
B4: Project Manager | G4: TRUE | H4: TRUE | K4: TRUE | L4: TRUE | Q4: TRUE | R4: TRUE
B5: Client Parter | M5: TRUE | N5: TRUE | P5: TRUE
B6: Finance
B7: Resource Manager
B9: Weekly Status Update Tab
B10: Responsible to populate | C10: Ref | D10: Project Name | E10: Client | F10: Week Ending | G10: Schedule RAG | H10: Resource RAG | I10: Scope RAG | J10: Budget RAG | K10: Overall RAG | L10: Key Flag / Comment | M10: Next Milestone | N10: Milestone Due | O10: Milestone Status | P10: PM Name | Q10: Last Updated
B11: Portfolio Office | C11: TRUE | D11: TRUE | E11: TRUE | P11: TRUE
B12: Project Manager | F12: TRUE | G12: TRUE | H12: TRUE | I12: TRUE | J12: TRUE | K12: TRUE | L12: TRUE | M12: TRUE | N12: TRUE | O12: TRUE | Q12: TRUE
B13: Client Parter
B14: Finance
B15: Resource Manager
B17: Risks and Issues Tab
B18: Responsible to populate | C18: Ref | D18: Project Name | E18: Client | F18: Phase | G18: Type | H18: Rating | I18: Description | J18: Impact if Unmitigated | K18: Mitigation / Action | L18: Owner | M18: Status | N18: Date Raised
B19: Portfolio Office | C19: TRUE | D19: TRUE | E19: TRUE
B20: Project Manager | F20: TRUE | G20: TRUE | H20: TRUE | I20: TRUE | J20: TRUE | K20: TRUE | L20: TRUE | M20: TRUE | N20: TRUE
B21: Client Parter
B22: Finance
B23: Resource Manager
B25: Commercial Register Tab
B26: Responsible to populate | C26: Ref | D26: Project Name | E26: Client | F26: CP Name | G26: Contract Value (£) | H26: Revenue Plan MTD (£) | I26: Revenue Actual MTD (£) | J26: Margin Forecast (%) | K26: Opportunity Name | L26: Pipeline Stage | M26: Pipeline Value (£) | N26: Repeat / New
B27: Portfolio Office | C27: TRUE | D27: TRUE | E27: TRUE
B28: Project Manager
B29: Client Parter | F29: TRUE | G29: TRUE | H29: TRUE | I29: TRUE | J29: TRUE | K29: TRUE | L29: TRUE | M29: TRUE | N29: TRUE
B30: Finance
B31: Resource Manager
B33: Resource and Utilisation Tab
B34: Responsible to populate | C34: Ref | D34: Name | E34: Practice | F34: Region | G34: Contract Hours/Wk | H34: Leave Hours | I34: Billable Hours | J34: Non-Billable Hours | K34: Utilisation % | L34: Assigned Project(s) | M34: Assignment Status | N34: Notes
B35: Portfolio Office | C35: TRUE
B36: Project Manager
B37: Client Parter
B38: Finance
B39: Resource Manager | D39: TRUE | E39: TRUE | F39: TRUE | G39: TRUE | H39: TRUE | I39: TRUE | J39: TRUE | K39: TRUE | L39: TRUE | M39: TRUE | N39: TRUE
B41: Client Satisfaction Tab
B42: Responsible to populate | C42: Ref | D42: Project Name | E42: Client | F42: Date Collected | G42: Score (1-5) | H42: Client Comment | I42: Collected By | J42: Next Collection Due
B43: Portfolio Office | C43: TRUE | D43: TRUE | E43: TRUE
B44: Project Manager
B45: Client Parter | F45: TRUE | G45: TRUE | H45: TRUE | I45: TRUE | J45: TRUE
...

Sheet ✅ Gov Checkpoints
A1: ✅ Gov Checkpoints | Portfolio Office — Central Source of Truth | Portfolio tracks evidence; delivery teams run the meetings
A2: GOVERNANCE CHECKPOINTS | Lifecycle: Bid/Proposal > Initiate > Plan > Delivery > Close | Delivery flow within Delivery phase: Design > Build > Test > Deploy
A3: Portfolio Office | B3: Portfolio Office | C3: Portfolio Office | D3: Portfolio Office | E3: Portfolio Office | F3: Portfolio Office | G3: PM | H3: PM | I3: PM | J3: PM | K3: PM | L3: PM | M3: Portfolio Office
A4: Portfolio Office | B4: Portfolio Office | C4: Portfolio Office | D4: Portfolio Office | E4: Portfolio Office | F4: Portfolio Office | G4: n/a Update Here | H4: n/a Update Here | I4: n/a Update Here | J4: n/a Update Here | K4: n/a Update Here | L4: n/a Update Here | M4: n/a Update Here
A5: Ref | B5: Phase | C5: Checkpoint | D5: Owner | E5: What it covers | F5: Evidence — how Portfolio Office tracks it | G5: P001 CRM Modernisation UKPN | UAT | H5: P002 ERP Integration UKPN | Build | I5: P003 Data Platform SSE | Discovery | J5: P004 Digital Strategy ENW | Discovery | K5: P005 Cyber Maturity Nat. Grid | Build | L5: P006 OT Security SP Energy | Discovery | M5: Notes / Evidence Detail
A6: B1 | B6: Bid/Proposal | C6: Bid / No-bid review | D6: Portfolio Office | E6: Portfolio Office confirms commercial viability, resource availability, margin expectations and strategic fit before committing to a bid. Hard gate — no bid submitted without Portfolio Office sign-off. | F6: Decision (Proceed / No-bid) recorded with rationale and Client Partner sign-off. Date and decision logged in register. Stored against project ref. | G6: Complete | H6: Complete | I6: Complete | J6: Complete | K6: Complete | L6: Complete
A7: B2 | B7: Bid/Proposal | C7: Technical solutioning sign-off | D7: Joint | E7: Delivery team presents proposed technical approach, stack, architecture and effort estimates. Portfolio confirms resource and timeline are realistic before submission. | F7: Solution summary doc or sign-off email filed. Date, attendees and any conditions recorded in Notes column. Portfolio records outcome — does not chair meeting. | G7: Complete | H7: Complete | I7: Complete | J7: Complete | K7: Complete | L7: Complete
A8: B3 | B8: Bid/Proposal | C8: Risk & assumptions register opened | D8: Joint | E8: Delivery raises key delivery risks and commercial assumptions in the bid. Portfolio validates completeness and realism before submission to client. | F8: Risk log version number and review date recorded. PM confirmation noted. Linked to Risks & Issues tab on award. | G8: Complete | H8: Complete | I8: Complete | J8: Complete | K8: Complete | L8: Complete
A9: I1 | B9: Initiate | C9: Project kick-off gate | D9: Portfolio Office | E9: Hard gate before any delivery work begins. Signed contract confirmed, project code issued, PM named, baseline scope and budget agreed. No work starts without this. | F9: Contract reference, project code, PM name and gate date recorded. Gate status = Pass / Conditional / Fail. Logged in Project Register. | G9: Complete | H9: Complete | I9: Complete | J9: Complete | K9: Complete | L9: In Progress
A10: I2 | B10: Initiate | C10: Project charter approved | D10: Joint | E10: Objectives, success criteria, constraints, exclusions, governance contacts and escalation path documented and agreed with client. | F10: Charter document version and client sign-off date recorded. Portfolio holds the approved charter. Any conditions noted. | G10: Complete | H10: Complete | I10: Complete | J10: Complete | K10: Complete | L10: In Progress
A11: I3 | B11: Initiate | C11: Stakeholder & RACI confirmed | D11: Portfolio Office | E11: Client-side contacts, internal nxzen team, escalation path and communication cadence agreed and documented. | F11: Named contacts and RACI version logged. Portfolio records confirmation date. Escalation path tested (email/call confirmed with client sponsor). | G11: Complete | H11: Complete | I11: Complete | J11: Complete | K11: Complete | L11: In Progress
A12: I4 | B12: Initiate | C12: Technical architecture review | D12: Delivery Team | E12: Delivery team presents proposed architecture to internal technical lead or CTO. Solution reviewed for quality, nxzen standards, risk and client constraints. | F12: Portfolio records: reviewed (Y/N), reviewer name, date, any conditions raised. Delivery team owns and runs the review. Portfolio logs outcome only. | G12: Complete | H12: Complete | I12: Complete | J12: Complete | K12: Complete | L12: In Progress
A13: P1 | B13: Plan | C13: Baseline plan approved | D13: Portfolio Office | E13: Project schedule, milestones, dependencies and critical path baselined and approved. Portfolio holds the approved baseline for all future change tracking. | F13: Baseline plan version saved with approval date and PM sign-off. Any variances from bid assumptions noted. Baseline locked in register. | G13: Complete | H13: Complete | I13: In Progress | J13: In Progress | K13: Complete | L13: Not Started
A14: P2 | B14: Plan | C14: Design review sign-off | D14: Delivery Team | E14: UX, architecture or data design reviewed and approved before build begins. Covers functional design, non-functional requirements and integration points. Entry gate to Build — no build starts without this. | F14: Portfolio records: sign-off received (Y/N), reviewer name, date, and whether any CRs were raised as a result. Delivery team runs the review. | G14: Complete | H14: Complete | I14: In Progress | J14: In Progress | K14: Complete | L14: Not Started
A15: P3 | B15: Plan | C15: Resource confirmed | D15: Joint | E15: Named individuals assigned to the project before delivery starts. Skill gaps identified. Interim or contractor resource plan agreed if gaps exist. | F15: Named resource list logged against project ref. Any gaps or contractor requirements flagged to Resource Manager. Confirmation date recorded. Linked to Resource tab. | G15: Complete | H15: Complete | I15: In Progress | J15: In Progress | K15: Complete | L15: Not Started
A16: P4 | B16: Plan | C16: Quality & test strategy agreed | D16: Delivery Team | E16: Test approach, environments, test types (SIT, UAT, regression), entry/exit criteria and client acceptance process defined and agreed before build begins. | F16: Test strategy document on file. Portfolio records: agreed (Y/N), date, UAT lead named (client and internal). Delivery team owns the document. | G16: Complete | H16: Complete | I16: In Progress | J16: In Progress | K16: Complete | L16: Not Started
A17: D1 | B17: Delivery | C17: Design sign-off (entry to Build) | D17: Delivery Team | E17: Functional and technical design formally signed off by client and internal lead before any build activity begins. Covers UI/UX, data model, integrations and non-functional requirements. | F17: Portfolio records: signed off (Y/N), client contact, internal reviewer, date. Any open design items that are conditional to build noted. Delivery team runs the review; Portfolio logs outcome. | G17: In Progress | H17: In Progress | I17: Not Started | J17: Not Started | K17: In Progress | L17: Not Started
... A26: C4 | B26: Close | C26: Project closure approved | D26: Portfolio Office | E26: Final sign-off that the project is complete. Covers: final financials reconciled, outcomes vs plan documented, client satisfaction score collected, resource released, project code closed in systems. | F26: Closure checklist completed. Final margin vs target recorded in Commercial tab. Client satisfaction score logged in ⭐ Client Satisfaction tab. Project status set to Closed in Project Register. | G26: Not Started | H26: Not Started | I26: Not Started | J26: Not Started | K26: Not Started | L26: Not Started
A28: Owner key: Portfolio Office = holds the gate, records evidence and escalates | Delivery Team = runs the meeting and produces the artefact | Joint = both must attend for the decision to be valid

Sheet 🗂 Project Register
A1: 🗂 Project Register | All Active nxzen UK Projects | Updated: see cell P2
A2: PROJECT IDENTITY | D2: DATES & PHASE | I2: COMMERCIAL | L2: OWNERSHIP | O2: STATUS
A3: Portfolio Office | B3: Portfolio Office | C3: Portfolio Office | D3: Portfolio Office | E3: PM | F3: PM | G3: Portfolio Office | H3: Portfolio Office | I3: PM | J3: PM | K3: CP | L3: CP | M3: Portfolio Office | N3: CP | O3: PM | P3: PM
A4: MS Dynamic Project Operations | B4: MS Dynamic Project Operations | C4: MS Dynamic Project Operations | D4: MS Dynamic Project Operations | E4: n/a Update Here | F4: n/a Update Here | G4: MS Dynamic Project Operations | H4: MS Dynamic Project Operations | I4: n/a Update Here | J4: n/a Update Here | K4: ZenX | L4: ZenX | M4: MS Dynamic Project Operations | N4: ZenX | O4: n/a Update Here | P4: n/a Update Here
A5: Ref | B5: Project Name | C5: Client | D5: Sub-Proposition / Practice | E5: Current Phase | F5: Status | G5: Start Date | H5: End Date (Baseline) | I5: End Date (Forecast) | J5: Days Slippage | K5: Contract Value (£) | L5: Margin Target (%) | M5: PM Name | N5: CP Name | O5: Project Code | P5: Notes
A6: GB01_P001074 | B6: Project - UKPN - Cyber Resilience Roles T&M | C6: UK Power Networks (Operations) Ltd | D6: Renewables & Engineering | F6: Active | G6: 45839 | H6: 46387 | M6: Amit Fadnavis | N6: Sudhakar Nalla
A7: GB01_P001021 | B7: Project - UKPN - Income Management Mavis Faster Staging | C7: UK Power Networks (Operations) Ltd | D7: Renewables & Engineering | F7: Active | G7: 46027 | H7: 46122 | I7: 46371 | M7: Danie Selvaraju | N7: Sudhakar Nalla
A8: GB01_P001073 | B8: Project - UKPN - Nexus IMIB | C8: UK Power Networks (Operations) Ltd | D8: Renewables & Engineering | E8: UAT | F8: Active | G8: 46054 | H8: 46265 | M8: MohamedMurshid S | N8: Sudhakar Nalla
B9: UKPN - Distance to Fault & CAS Pole Pilot | C9: UK Power Networks (Operations) Ltd | D9: Renewables & Engineering | F9: Active | G9: 46082 | H9: 46387 | M9: Vasupradha | N9: Sudhakar Nalla | P9: New project
A10: GB01_P001005 | B10: Project - Eirgrid - Eirgrid PSSE to Power Factory | C10: EirGrid plc | D10: Renewables & Engineering | F10: On Hold | G10: 45870 | H10: 46934 | M10: Rodrigo Merino | N10: Rodrigo Merino | P10: The project has been placed on hold and may potentially be terminated.
A11: GB01_P001006 | B11: Project - Eirgrid - Eirgird Product Specialist T&M | C11: EirGrid plc | D11: Renewables & Engineering | F11: Active | G11: 45931 | H11: 46142 | M11: Rodrigo Merino | N11: Rodrigo Merino | P11: The project may be extended by a further three months - In discussion
A12: GB01_P001010 | B12: Project - ENWL - SAP Projects | C12: Electricity North West Limited | D12: Renewables & Engineering | F12: Active | G12: 45748 | H12: 46477 | M12: TamoghnaMihirDas gupta | N12: David Butcher
B13: ENWL - Project Manager - IT Resilience SMR - TnM | C13: Electricity North West Limited | D13: Renewables & Engineering | F13: Active | G13: 46143 | H13: 46325 | M13: TamoghnaMihirDas gupta | N13: David Butcher | P13: New project
B14: WWU - Deed Digitalisation | C14: Wales & West Utilities | D14: Renewables & Engineering | F14: Active | G14: 46113 | H14: 46418 | M14: TamoghnaMihirDas gupta | N14: Martin Ridley | P14: New project
B15: WWU - Service Suite Upgrade & MFT | C15: Wales & West Utilities | D15: Renewables & Engineering | E15: Design | F15: Active | G15: 46113 | H15: 46387 | M15: TamoghnaMihirDas gupta | N15: Martin Ridley | P15: New project
A16: GB01_P001075 | B16: Project - WWU - Open Text | C16: Wales & West Utilities | D16: Renewables & Engineering | E16: Design | F16: Active | G16: 46089.375 | H16: 46418 | M16: TamoghnaMihirDas gupta | N16: Martin Ridley
A17: GB01_P001028 | B17: Project - WWU- SAP Simplification Item - S/4 | C17: Wales & West Utilities | D17: Renewables & Engineering | F17: Active | G17: 45665 | H17: 46356 | M17: TamoghnaMihirDas gupta | N17: Martin Ridley
A18: GB01_P001026 | B18: Project - WWU - S4 Resource and S4 Project Support New - FY26 | C18: Wales & West Utilities | D18: Renewables & Engineering | F18: Active | G18: 45748 | H18: 46387 | M18: TamoghnaMihirDas gupta | N18: Martin Ridley
A19: GB01_P001070 | B19: Project - SGN - Dev Test FPP | C19: Scotia Gas Networks Limited | D19: Renewables & Engineering | F19: Active | G19: 46113 | H19: 46477 | M19: Anoop Prabhu | N19: Alex Pitcher | P19: Project consists of 5 FP SOW's
A20: GB01_P001069 | B20: Project - SGN - Dev Test T&M | C20: Scotia Gas Networks Limited | D20: Renewables & Engineering | F20: Active | G20: 46113 | H20: 46477 | M20: Anoop Prabhu | N20: Alex Pitcher | P20: Project consists of T&M SOW's

Sheet 🚦 Weekly Status Update
A1: 🚦 Weekly Status Update | Complete by Wednesday EOD | PM-owned
A2: PROJECT ID | E2: RAG STATUS - REFER TO CRITERIA IN INSTRUCTIONS (this week) | J2: KEY FLAG / COMMENT | K2: MILESTONE | N2: GOVERNANCE
A3: Portfolio Office | B3: Portfolio Office | C3: 17.22 | D3: PM | E3: PM | F3: PM | G3: PM | H3: PM | I3: PM | J3: PM | K3: PM | L3: PM | M3: PM | N3: Portfolio Office | O3: PM
A4: MS Dynamic Project Operations | B4: MS Dynamic Project Operations | C4: MS Dynamic Project Operations | D4: n/a Update Here | E4: n/a Update Here | F4: n/a Update Here | G4: n/a Update Here | H4: n/a Update Here | I4: n/a Update Here | J4: n/a Update Here | K4: n/a Update Here | L4: n/a Update Here | M4: n/a Update Here | N4: MS Dynamic Project Ops | O4: n/a Update Here
A5: Ref | B5: Project Name | C5: Client | D5: Week Ending | E5: Schedule RAG | F5: Resource RAG | G5: Scope RAG | H5: Budget RAG | I5: Overall RAG | J5: Key Flag / Comment (mandatory if any Red) | K5: Next Milestone | L5: Milestone Due | M5: Milestone Status | N5: PM Name | O5: Last Updated
A6: ='🗂 Project Register'!A6 -> GB01_P001074 | B6: ='🗂 Project Register'!B6 -> Project - UKPN - Cyber Resilience Roles T&M | C6: ='🗂 Project Register'!C6 -> UK Power Networks (Operations) Ltd | D6: 46150 | E6: Green | F6: Green | G6: Green | H6: Green | I6: Green | J6: 05/05: End of May PO to be confirmed. At Risk but client assured | K6: PO confirmation | L6: 46173 | M6: At Risk | N6: ='🗂 Project Register'!M6 -> Amit Fadnavis | O6: 46147
A7: ='🗂 Project Register'!A7 -> GB01_P001021 | B7: ='🗂 Project Register'!B7 -> Project - UKPN - Income Management Mavis Faster Staging | C7: ='🗂 Project Register'!C7 -> UK Power Networks (Operations) Ltd | D7: 46150 | E7: Green | F7: Green | G7: Green | H7: Green | I7: Green | J7: 28/04: Project continued until Dec’26 | M7: On Track | N7: ='🗂 Project Register'!M7 -> Danie Selvaraju | O7: 46140
A8: ='🗂 Project Register'!A8 -> GB01_P001073 | B8: ='🗂 Project Register'!B8 -> Project - UKPN - Nexus IMIB | C8: ='🗂 Project Register'!C8 -> UK Power Networks (Operations) Ltd | D8: 46150 | E8: Amber | F8: Green | G8: Green | H8: Green | I8: Amber | J8: 28/04: Very tight timelines. UAT started 27/04 and client resourcing not sufficient to meet deadlines, so we have needed to add in more resource to complete. | K8: UAT Complete | M8: At Risk | N8: ='🗂 Project Register'!M8 -> MohamedMurshid S | O8: 46140
A9: ='🗂 Project Register'!A9 -> 0 | B9: ='🗂 Project Register'!B9 -> UKPN - Distance to Fault & CAS Pole Pilot | C9: ='🗂 Project Register'!C9 -> UK Power Networks (Operations) Ltd | D9: 46150 | E9: Green | F9: Green | G9: Green | H9: Green | I9: Green | J9: 05/05: Reduce timelines for pilot delivery. | K9: Workshop | L9: 46155 | M9: On Track | N9: ='🗂 Project Register'!M9 -> Vasupradha | O9: 46147
A10: ='🗂 Project Register'!A10 -> GB01_P001005 | B10: ='🗂 Project Register'!B10 -> Project - Eirgrid - Eirgrid PSSE to Power Factory | C10: ='🗂 Project Register'!C10 -> EirGrid plc | D10: 46150 | E10: Red | F10: Green | G10: Red | H10: Green | I10: Red | J10: 05/05: Scheduling call with Procurement. £50k at risk. | K10: Confirm proj statius | M10: At Risk | N10: ='🗂 Project Register'!M10 -> Rodrigo Merino | O10: 46147
A11: ='🗂 Project Register'!A11 -> GB01_P001006 | B11: ='🗂 Project Register'!B11 -> Project - Eirgrid - Eirgird Product Specialist T&M | C11: ='🗂 Project Register'!C11 -> EirGrid plc | D11: 46150 | E11: Green | F11: Green | G11: Green | H11: Green | I11: Green | J11: 27/04: Currently discussing 3-month extension from under mid-May current PO | N11: ='🗂 Project Register'!M11 -> Rodrigo Merino | O11: 46139
A12: ='🗂 Project Register'!A12 -> GB01_P001010 | B12: ='🗂 Project Register'!B12 -> Project - ENWL - SAP Projects | C12: ='🗂 Project Register'!C12 -> Electricity North West Limited | D12: 46150 | E12: Green | F12: Green | G12: Green | H12: Green | I12: Green | J12: 06/05: CR status is green. Extension of 1 week accepted by client. ​ Separately the stabilization is in progress and on track against plan. | K12: Complete Stabilisation plan | M12: On Track | N12: ='🗂 Project Register'!M12 -> TamoghnaMihirDas gupta | O12: 46148
A13: ='🗂 Project Register'!A13 -> 0 | B13: ='🗂 Project Register'!B13 -> ENWL - Project Manager - IT Resilience SMR - TnM | C13: ='🗂 Project Register'!C13 -> Electricity North West Limited | D13: 46150 | E13: Green | F13: Green | G13: Green | H13: Green | I13: Green | J13: 29/04: Srinivasan Neelakantan has been onboarded and working from SP ENW Location from 20th April. | N13: ='🗂 Project Register'!M13 -> TamoghnaMihirDas gupta | O13: 46141
A14: ='🗂 Project Register'!A14 -> 0 | B14: ='🗂 Project Register'!B14 -> WWU - Deed Digitalisation | C14: ='🗂 Project Register'!C14 -> Wales & West Utilities | D14: 46150 | E14: Green | F14: Green | G14: Green | H14: Green | I14: Green | J14: 06/05: Client feedback to be incorporated into design and to be played back 07/05 during the Architecture Review Board (ARB) | K14: Design review at ARB | L14: 46149 | M14: On Track | N14: ='🗂 Project Register'!M14 -> TamoghnaMihirDas gupta | O14: 46148
A15: ='🗂 Project Register'!A15 -> 0 | B15: ='🗂 Project Register'!B15 -> WWU - Service Suite Upgrade & MFT | C15: ='🗂 Project Register'!C15 -> Wales & West Utilities | D15: 46150 | E15: Green | F15: Green | G15: Green | H15: Green | I15: Green | J15: 06/05: Received additional scope from client and working on impact assessment currently, to be shared next week. Project still in design phase. | K15: Agree scope | M15: On Track | N15: ='🗂 Project Register'!M15 -> TamoghnaMihirDas gupta | O15: 46148
A16: ='🗂 Project Register'!A16 -> GB01_P001075 | B16: ='🗂 Project Register'!B16 -> Project - WWU - Open Text | C16: ='🗂 Project Register'!C16 -> Wales & West Utilities | D16: 46150 | E16: Amber | F16: Amber | G16: Amber | H16: Amber | I16: Amber | J16: 06/05: New plan is being baselined and CR being agreed with the client. Once plan baselined and CR agreed, we can anticipate move back to green. | K16: Meet with WWU Team | M16: On Track | N16: ='🗂 Project Register'!M16 -> TamoghnaMihirDas gupta | O16: 46148
A17: ='🗂 Project Register'!A17 -> GB01_P001028 | B17: ='🗂 Project Register'!B17 -> Project - WWU- SAP Simplification Item - S/4 | C17: ='🗂 Project Register'!C17 -> Wales & West Utilities | D17: 46150 | E17: Green | F17: Green | G17: Green | H17: Green | I17: Green | K17: Submit work order | N17: ='🗂 Project Register'!M17 -> TamoghnaMihirDas gupta | O17: 46141
A18: ='🗂 Project Register'!A18 -> GB01_P001026 | B18: ='🗂 Project Register'!B18 -> Project - WWU - S4 Resource and S4 Project Support New - FY26 | C18: ='🗂 Project Register'!C18 -> Wales & West Utilities | D18: 46150 | E18: Green | F18: Green | G18: Green | H18: Green | I18: Green | J18: NGM DBP Decom – delivered and handover in progress | K18: Complete handover | N18: ='🗂 Project Register'!M18 -> TamoghnaMihirDas gupta | O18: 46141
A19: ='🗂 Project Register'!A19 -> GB01_P001070 | B19: ='🗂 Project Register'!B19 -> Project - SGN - Dev Test FPP | C19: ='🗂 Project Register'!C19 -> Scotia Gas Networks Limited | D19: 46150 | E19: Red | F19: Green | G19: Green | H19: Red | I19: Red | J19: 07/05: Alex (CP) and project sponsor from SNG have aligned. SGN has not confirmed the testing start date. (Sudha). Need to re-baseline plan and commercials etc. Alex is on top of this issue. Trend is the same as previous week. | K19: 07/05: IBM team onboarded today, kick off complete. (Praveen) | L19: 46139 | M19: Complete | N19: ='🗂 Project Register'!M19 -> Anoop Prabhu | O19: 46149
A20: ='🗂 Project Register'!A20 -> GB01_P001069 | B20: ='🗂 Project Register'!B20 -> Project - SGN - Dev Test T&M | C20: ='🗂 Project Register'!C20 -> Scotia Gas Networks Limited | D20: 46150 | E20: Green | F20: Green | G20: Green | H20: Green | I20: Green | J20: 07/05: Tracking green, no issues. | N20: ='🗂 Project Register'!M20 -> Anoop Prabhu | O20: 46149

Sheet ⚠️ Risks & Issues
A1: ⚠️ Risks & Issues Register | PM-owned | Updated Weekly
A2: PROJECT | E2: RISK / ISSUE DETAIL | I2: MANAGEMENT
A3: Portfolio Office | B3: Portfolio Office | C3: Portfolio Office | D3: PM | E3: PM | F3: PM | G3: PM | H3: PM | I3: PM | J3: PM | K3: PM | L3: PM
A4: MS Dynamic Proj Ops | B4: MS Dynamic Proj Ops | C4: MS Dynamic Proj Ops | D4: Current Proj Status Excel | E4: RAID | F4: RAID | G4: RAID | H4: RAID | I4: RAID | J4: RAID | K4: RAID | L4: RAID
A5: Ref | B5: Project Name | C5: Client | D5: Phase | E5: Type | F5: Rating | G5: Description | H5: Impact if Unmitigated | I5: Mitigation / Action | J5: Owner | K5: Status | L5: Date Raised
A6: ='🗂 Project Register'!A6 -> GB01_P001074 | B6: ='🗂 Project Register'!B6 -> Project - UKPN - Cyber Resilience Roles T&M | C6: ='🗂 Project Register'!C6 -> UK Power Networks (Operations) Ltd | D6: ='🗂 Project Register'!E6 -> 0
A7: ='🗂 Project Register'!A7 -> GB01_P001021 | B7: ='🗂 Project Register'!B7 -> Project - UKPN - Income Management Mavis Faster Staging | C7: ='🗂 Project Register'!C7 -> UK Power Networks (Operations) Ltd | D7: ='🗂 Project Register'!E7 -> 0
A8: ='🗂 Project Register'!A8 -> GB01_P001073 | B8: ='🗂 Project Register'!B8 -> Project - UKPN - Nexus IMIB | C8: ='🗂 Project Register'!C8 -> UK Power Networks (Operations) Ltd | D8: ='🗂 Project Register'!E8 -> UAT
A9: ='🗂 Project Register'!A9 -> 0 | B9: ='🗂 Project Register'!B9 -> UKPN - Distance to Fault & CAS Pole Pilot | C9: ='🗂 Project Register'!C9 -> UK Power Networks (Operations) Ltd | D9: ='🗂 Project Register'!E9 -> 0
A10: ='🗂 Project Register'!A10 -> GB01_P001005 | B10: ='🗂 Project Register'!B10 -> Project - Eirgrid - Eirgrid PSSE to Power Factory | C10: ='🗂 Project Register'!C10 -> EirGrid plc | D10: ='🗂 Project Register'!E10 -> 0 | E10: Risk | F10: High | G10: Risk of non-payment as client not satisfied by work completed | I10: CP scheduling meeting with Procurement to review and discuss next steps | J10: R Merino | K10: In Progress | L10: 46143
A11: ='🗂 Project Register'!A11 -> GB01_P001006 | B11: ='🗂 Project Register'!B11 -> Project - Eirgrid - Eirgird Product Specialist T&M | C11: ='🗂 Project Register'!C11 -> EirGrid plc | D11: ='🗂 Project Register'!E11 -> 0
A12: ='🗂 Project Register'!A12 -> GB01_P001010 | B12: ='🗂 Project Register'!B12 -> Project - ENWL - SAP Projects | C12: ='🗂 Project Register'!C12 -> Electricity North West Limited | D12: ='🗂 Project Register'!E12 -> 0 | E12: Risk | F12: Medium | G12: SAP BASIS and security – team composition is currently lacking skills | I12: nxzen currently building in house team for SAP BASIS and security across all account. 06/05: No further update. | J12: Tamo / Solman | K12: In Progress | L12: 46141
A13: ='🗂 Project Register'!A13 -> 0 | B13: ='🗂 Project Register'!B13 -> ENWL - Project Manager - IT Resilience SMR - TnM | C13: ='🗂 Project Register'!C13 -> Electricity North West Limited | D13: ='🗂 Project Register'!E13 -> 0
A14: ='🗂 Project Register'!A14 -> 0 | B14: ='🗂 Project Register'!B14 -> WWU - Deed Digitalisation | C14: ='🗂 Project Register'!C14 -> Wales & West Utilities | D14: ='🗂 Project Register'!E14 -> 0 | E14: Risk | F14: Medium | G14: DEED Digitilisation solution – feedback on fitting client requirements | I14: 06/05: Feedback received but probability reduced. | J14: Nirmal Paul + Akhil Gupta | K14: In Progress | L14: 46141
A15: ='🗂 Project Register'!A15 -> 0 | B15: ='🗂 Project Register'!B15 -> WWU - Service Suite Upgrade & MFT | C15: ='🗂 Project Register'!C15 -> Wales & West Utilities | D15: ='🗂 Project Register'!E15 -> Design | E15: Risk | F15: High | G15: Secure MFT - Azure infrastructure Environment readiness / preparation is getting delayed. | I15: 06/05: Risk of further slippage beyond the change request. | J15: Tamo | K15: In Progress | L15: 45982
A16: ='🗂 Project Register'!A17 -> GB01_P001028 | B16: ='🗂 Project Register'!B17 -> Project - WWU- SAP Simplification Item - S/4 | C16: ='🗂 Project Register'!C17 -> Wales & West Utilities | D16: ='🗂 Project Register'!E17 -> 0 | E16: Risk | F16: Medium | G16: Risk on Version Compatibilities mismatch | I16: 06/05: clarification received | J16: Venoje | K16: Closed | L16: 46141
A17: ='🗂 Project Register'!A18 -> GB01_P001026 | B17: ='🗂 Project Register'!B18 -> Project - WWU - S4 Resource and S4 Project Support New - FY26 | C17: ='🗂 Project Register'!C18 -> Wales & West Utilities | D17: ='🗂 Project Register'!E18 -> 0 | E17: Risk | F17: Medium | G17: Risk of Delay in HLD Approval will have impact in Start of Development Activities | H17: Note: Not clear which piece of work the risk is related to so have selected GB01_P001026 | I17: 06/05: Still open, probability reduced | J17: Venoje | K17: In Progress | L17: 46141
A18: GB01_P0001026 | B18: ='🗂 Project Register'!B18 -> Project - WWU - S4 Resource and S4 Project Support New - FY26 | C18: ='🗂 Project Register'!C18 -> Wales & West Utilities | D18: ='🗂 Project Register'!E18 -> 0 | E18: Risk | F18: Medium | G18: No agreement on the Level of completion of LLD to commence development activities | H18: Note: Not clear which piece of work the risk is related to so have selected GB01_P001026 | I18: 06/05: Still open, probability reduced | J18: Venoje | K18: In Progress | L18: 46141
A19: ='🗂 Project Register'!A19 -> GB01_P001070 | B19: ='🗂 Project Register'!B19 -> Project - SGN - Dev Test FPP | C19: ='🗂 Project Register'!C19 -> Scotia Gas Networks Limited | D19: ='🗂 Project Register'!E19 -> 0 | E19: Risk | F19: Medium | G19: Risk on IBM Infra being not supportive on Application support | I19: 07/05: Anoop to escalate it with SGN. In progress | J19: Anoop | K19: In Progress | L19: 46149
A20: ='🗂 Project Register'!A20 -> GB01_P001069 | B20: ='🗂 Project Register'!B20 -> Project - SGN - Dev Test T&M | C20: ='🗂 Project Register'!C20 -> Scotia Gas Networks Limited | D20: ='🗂 Project Register'!E20 -> 0 | E20: Risk | F20: Medium | G20: We may lose business to competitors for Gas Control related work due to lack of skilled resources in the team | I20: 07/05: Trying to support new resource starting next week, 2 days per week. June full time. Alex to confirm. If not available, revert to contractor. | J20: Vikas | K20: In Progress | L20: 46149

Sheet 💼 Commercial
A1: 💼 Commercial Register | CP-owned | Updated Monthly
A2: PROJECT | E2: REVENUE & MARGIN | I2: PIPELINE
A3: Portfolio Office | B3: Portfolio Office | C3: Portfolio Office | D3: CP Name | E3: CP Name | F3: CP Name | G3: CP Name | H3: CP Name | I3: CP Name | J3: CP Name | K3: CP Name | L3: CP Name
A4: MS Dynamic Proj Ops | B4: MS Dynamic Proj Ops | C4: MS Dynamic Proj Ops
A5: Ref | B5: Project Name | C5: Client | D5: CP Name | E5: Contract Value (£) | F5: Revenue Plan MTD (£) | G5: Revenue Actual MTD (£) | H5: Margin Forecast (%) | I5: Opportunity Name | J5: Pipeline Stage | K5: Pipeline Value (£) | L5: Repeat / New
A6: ='🗂 Project Register'!A6 -> GB01_P001074 | B6: ='🗂 Project Register'!B6 -> Project - UKPN - Cyber Resilience Roles T&M | C6: ='🗂 Project Register'!C6 -> UK Power Networks (Operations) Ltd | D6: ='🗂 Project Register'!N6 -> Sudhakar Nalla
A7: ='🗂 Project Register'!A7 -> GB01_P001021 | B7: ='🗂 Project Register'!B7 -> Project - UKPN - Income Management Mavis Faster Staging | C7: ='🗂 Project Register'!C7 -> UK Power Networks (Operations) Ltd | D7: ='🗂 Project Register'!N7 -> Sudhakar Nalla
A8: ='🗂 Project Register'!A8 -> GB01_P001073 | B8: ='🗂 Project Register'!B8 -> Project - UKPN - Nexus IMIB | C8: ='🗂 Project Register'!C8 -> UK Power Networks (Operations) Ltd | D8: ='🗂 Project Register'!N8 -> Sudhakar Nalla
A9: ='🗂 Project Register'!A9 -> 0 | B9: ='🗂 Project Register'!B9 -> UKPN - Distance to Fault & CAS Pole Pilot | C9: ='🗂 Project Register'!C9 -> UK Power Networks (Operations) Ltd | D9: ='🗂 Project Register'!N9 -> Sudhakar Nalla
A10: ='🗂 Project Register'!A10 -> GB01_P001005 | B10: ='🗂 Project Register'!B10 -> Project - Eirgrid - Eirgrid PSSE to Power Factory | C10: ='🗂 Project Register'!C10 -> EirGrid plc | D10: ='🗂 Project Register'!N10 -> Rodrigo Merino
A11: ='🗂 Project Register'!A11 -> GB01_P001006 | B11: ='🗂 Project Register'!B11 -> Project - Eirgrid - Eirgird Product Specialist T&M | C11: ='🗂 Project Register'!C11 -> EirGrid plc | D11: ='🗂 Project Register'!N11 -> Rodrigo Merino
A12: ='🗂 Project Register'!A12 -> GB01_P001010 | B12: ='🗂 Project Register'!B12 -> Project - ENWL - SAP Projects | C12: ='🗂 Project Register'!C12 -> Electricity North West Limited | D12: ='🗂 Project Register'!N12 -> David Butcher
A13: ='🗂 Project Register'!A13 -> 0 | B13: ='🗂 Project Register'!B13 -> ENWL - Project Manager - IT Resilience SMR - TnM | C13: ='🗂 Project Register'!C13 -> Electricity North West Limited | D13: ='🗂 Project Register'!N13 -> David Butcher
A14: ='🗂 Project Register'!A14 -> 0 | B14: ='🗂 Project Register'!B14 -> WWU - Deed Digitalisation | C14: ='🗂 Project Register'!C14 -> Wales & West Utilities | D14: ='🗂 Project Register'!N14 -> Martin Ridley
A15: ='🗂 Project Register'!A15 -> 0 | B15: ='🗂 Project Register'!B15 -> WWU - Service Suite Upgrade & MFT | C15: ='🗂 Project Register'!C15 -> Wales & West Utilities | D15: ='🗂 Project Register'!N15 -> Martin Ridley
A16: ='🗂 Project Register'!A16 -> GB01_P001075 | B16: ='🗂 Project Register'!B16 -> Project - WWU - Open Text | C16: ='🗂 Project Register'!C16 -> Wales & West Utilities | D16: ='🗂 Project Register'!N16 -> Martin Ridley
A17: ='🗂 Project Register'!A17 -> GB01_P001028 | B17: ='🗂 Project Register'!B17 -> Project - WWU- SAP Simplification Item - S/4 | C17: ='🗂 Project Register'!C17 -> Wales & West Utilities | D17: ='🗂 Project Register'!N17 -> Martin Ridley
... A20: ='🗂 Project Register'!A20 -> GB01_P001069 | B20: ='🗂 Project Register'!B20 -> Project - SGN - Dev Test T&M | C20: ='🗂 Project Register'!C20 -> Scotia Gas Networks Limited | D20: ='🗂 Project Register'!N20 -> Alex Pitcher

Sheet 👥 Resource & Utilisation
A1: 👥 Resource & Utilisation | Resource Manager-owned | Updated Weekly
A2: RESOURCE | F2: HOURS (this week) | J2: ASSIGNMENT
A3: Portfolio Office | B3: Resource Mgr | C3: Resource Mgr | D3: Resource Mgr | E3: Resource Mgr | F3: Resource Mgr | G3: Resource Mgr | H3: Resource Mgr | I3: Resource Mgr | J3: Resource Mgr | K3: Resource Mgr | L3: Resource Mgr
A4: MS Dynamic Proj Ops | B4: HR System* | C4: HR System* | D4: HR System* | E4: HR System* | F4: MS Dynamics Timesheet | G4: MS Dynamics Timesheet | H4: MS Dynamics Timesheet | I4: Resource Report** | J4: MS Dynamics Timesheet | K4: Resource Report** | L4: Resource Report**
A5: Ref | B5: Name | C5: Practice | D5: Region | E5: Contract Hours/Wk | F5: Leave Hours | G5: Billable Hours | H5: Non-Billable Hours | I5: Utilisation % | J5: Assigned Project(s) | K5: Assignment Status | L5: Notes
A6: R001 | B6: Danie Selvaraju | C6: Apps & Development | D6: UK | E6: 37.5 | F6: 0 | G6: 35 | H6: 2.5 | I6: =G6/(E6-F6) -> 0.93333333 | J6: P001 | K6: Assigned
A7: R002 | B7: Sam Lee | C7: Data Intelligence & AI | D7: UK | E7: 37.5 | F7: 0 | G7: 30 | H7: 7.5 | I7: =G7/(E7-F7) -> 0.8 | J7: P002 | K7: Assigned
A8: R003 | B8: Priya Patel | C8: Data Intelligence & AI | D8: UK | E8: 37.5 | F8: 0 | G8: 37.5 | H8: 0 | I8: =G8/(E8-F8) -> 1 | J8: P003 | K8: Assigned
A9: R004 | B9: Tom Hughes | C9: Renewables & Engineering | D9: UK | E9: 37.5 | F9: 7.5 | G9: 25 | H9: 5 | I9: =G9/(E9-F9) -> 0.83333333 | J9: P004 | K9: Assigned | L9: Part week - annual leave Mon-Tue
A10: R005 | B10: Anna Chen | C10: Cyber Security | D10: UK | E10: 37.5 | F10: 0 | G10: 37.5 | H10: 0 | I10: =G10/(E10-F10) -> 1 | J10: P005 | K10: Assigned
A11: R006 | B11: James Obi | C11: OT | D11: UK | E11: 37.5 | F11: 0 | G11: 30 | H11: 7.5 | I11: =G11/(E11-F11) -> 0.8 | J11: P006 | K11: Assigned
A12: R007 | B12: Ben Nair | C12: Data Intelligence & AI | D12: India | E12: 40 | F12: 0 | G12: 36 | H12: 4 | I12: =G12/(E12-F12) -> 0.9 | J12: P002, P003 | K12: Assigned
A13: R008 | B13: Meera Sharma | C13: Apps & Development | D13: India | E13: 40 | F13: 0 | G13: 40 | H13: 0 | I13: =G13/(E13-F13) -> 1 | J13: P001 | K13: Assigned
A14: R009 | B14: Chris Tate | C14: Renewables & Engineering | D14: UK | E14: 37.5 | F14: 0 | G14: 0 | H14: 37.5 | I14: =G14/(E14-F14) -> 0 | J14: Unassigned | K14: Bench | L14: Available for new project
A15: R010 | B15: Fatima Al-Hassan | C15: Cyber Security | D15: UK | E15: 37.5 | F15: 0 | G15: 20 | H15: 17.5 | I15: =G15/(E15-F15) -> 0.53333333 | J15: P005 | K15: Part-assigned | L15: 50% capacity only - internal training
A17: * Need to find out name of system / source?
A18: ** Assuming there is a spreadsheet or tool we use to manage resource / demand

Sheet ⭐ Client Satisfaction
A1: ⭐ Client Satisfaction | CP-owned | Collected Monthly / At Milestone
A2: Rate delivery 1–5: 5 = Exceeds expectations. 4 = Meets expectations. 3 = Mostly met. 2 = Below expectations. 1 = Significantly below.
A3: Portfolio Office | B3: Portfolio Office | C3: Portfolio Office | D3: CP | E3: CP | F3: CP | G3: CP | H3: CP
A4: MS Dynamic Proj Ops | B4: MS Dynamic Proj Ops | C4: MS Dynamic Proj Ops | D4: Client Sat Survey* | E4: Client Sat Survey* | F4: Client Sat Survey* | G4: Client Sat Survey* | H4: Client Sat Survey*
A5: Ref | B5: Project Name | C5: Client | D5: Date Collected | E5: Score (1-5) | F5: Client Comment | G5: Collected By | H5: Next Collection Due
A6: ='🗂 Project Register'!A6 -> GB01_P001074 | B6: ='🗂 Project Register'!B6 -> Project - UKPN - Cyber Resilience Roles T&M | C6: ='🗂 Project Register'!C6 -> UK Power Networks (Operations) Ltd | D6: 46147 | E6: 4
A7: ='🗂 Project Register'!A7 -> GB01_P001021 | B7: ='🗂 Project Register'!B7 -> Project - UKPN - Income Management Mavis Faster Staging | C7: ='🗂 Project Register'!C7 -> UK Power Networks (Operations) Ltd | D7: 46140 | E7: 4
A8: ='🗂 Project Register'!A8 -> GB01_P001073 | B8: ='🗂 Project Register'!B8 -> Project - UKPN - Nexus IMIB | C8: ='🗂 Project Register'!C8 -> UK Power Networks (Operations) Ltd | D8: 46140 | E8: 4
A9: ='🗂 Project Register'!A9 -> 0 | B9: ='🗂 Project Register'!B9 -> UKPN - Distance to Fault & CAS Pole Pilot | C9: ='🗂 Project Register'!C9 -> UK Power Networks (Operations) Ltd | D9: 46147 | E9: 2
A10: ='🗂 Project Register'!A10 -> GB01_P001005 | B10: ='🗂 Project Register'!B10 -> Project - Eirgrid - Eirgrid PSSE to Power Factory | C10: ='🗂 Project Register'!C10 -> EirGrid plc | D10: 46143 | E10: 1 | F10: No agreement with client re overall project status
A11: ='🗂 Project Register'!A11 -> GB01_P001006 | B11: ='🗂 Project Register'!B11 -> Project - Eirgrid - Eirgird Product Specialist T&M | C11: ='🗂 Project Register'!C11 -> EirGrid plc | D11: 46139 | E11: 4
A12: ='🗂 Project Register'!A12 -> GB01_P001010 | B12: ='🗂 Project Register'!B12 -> Project - ENWL - SAP Projects | C12: ='🗂 Project Register'!C12 -> Electricity North West Limited | D12: 46148 | E12: 4 | F12: Stabilisation process in progress and on track
A13: ='🗂 Project Register'!A13 -> 0 | B13: ='🗂 Project Register'!B13 -> ENWL - Project Manager - IT Resilience SMR - TnM | C13: ='🗂 Project Register'!C13 -> Electricity North West Limited | D13: 46141 | E13: 4
A14: ='🗂 Project Register'!A14 -> 0 | B14: ='🗂 Project Register'!B14 -> WWU - Deed Digitalisation | C14: ='🗂 Project Register'!C14 -> Wales & West Utilities
A15: ='🗂 Project Register'!A15 -> 0 | B15: ='🗂 Project Register'!B15 -> WWU - Service Suite Upgrade & MFT | C15: ='🗂 Project Register'!C15 -> Wales & West Utilities
A16: ='🗂 Project Register'!A16 -> GB01_P001075 | B16: ='🗂 Project Register'!B16 -> Project - WWU - Open Text | C16: ='🗂 Project Register'!C16 -> Wales & West Utilities
A17: ='🗂 Project Register'!A17 -> GB01_P001028 | B17: ='🗂 Project Register'!B17 -> Project - WWU- SAP Simplification Item - S/4 | C17: ='🗂 Project Register'!C17 -> Wales & West Utilities
A18: ='🗂 Project Register'!A18 -> GB01_P001026 | B18: ='🗂 Project Register'!B18 -> Project - WWU - S4 Resource and S4 Project Support New - FY26 | C18: ='🗂 Project Register'!C18 -> Wales & West Utilities
A19: ='🗂 Project Register'!A19 -> GB01_P001070 | B19: ='🗂 Project Register'!B19 -> Project - SGN - Dev Test FPP | C19: ='🗂 Project Register'!C19 -> Scotia Gas Networks Limited | E19: 3
A20: ='🗂 Project Register'!A20 -> GB01_P001069 | B20: ='🗂 Project Register'!B20 -> Project - SGN - Dev Test T&M | C20: ='🗂 Project Register'!C20 -> Scotia Gas Networks Limited | E20: 5
