Workbook

Sheet Cover sheet
A1: Version | B1: Status | C1: Date | D1: Author | E1: Comments
A2: v0.1 | B2: Old | C2: 46127 | D2: Laura Hargrave | E2: Revised with feedback from Martin Wells: utilization by practice and sub-proposition reference. Additionally added overview slide.
A3: v0.2 | B3: Old | C3: 46139 | D3: Alf Pendlebury | E3: All fields reviewed and updates applied where necessary. Validators assigned to each KPI / measure, validation date field for each measure. Capability Summary updated. Notes section updated.
A4: v0.3 | B4: Old | C4: 46139 | D4: Alf Pendlebury | E4: Added separate measure for Overall RAG status, redefined overall RAG criteria. Applied formatting / cosmetic changes.
A5: v0.4 | B5: Current | C5: 46148 | D5: Alf Pendlebury | E5: Added new column "Release" to show in which release each a particular measure will be in (initial estimates & see Note 4). Updated metrics post validation review (Fin & Delivery). Added Cost RAG per project measure & Deals > 4 months in the pipeline. Added Deleted Metrics tab. Capability summary updated. Added Utilisation by Practice measures for Cyber Security, Apps & Development and OT practices.
A7: Notes:
A8: N1: Managed Services are excluded from all KPI's & measures in this catalogue. N2: This catalogue refers only to the UK & India only. N3: For the purpose of this catalogue, a project currently in delivery is referred to as an "active project." N4: Product release dates TBC

Sheet Metric Catalogue
B1: nxzen Portfolio Office | Metric Definition Catalogue | DRAFT — April 2026
B2: METRIC IDENTITY | F2: DEFINITION | I2: DATA & GOVERNANCE | N2: CAPABILITY ASSESSMENT | U2: DASHBOARD | X2: THRESHOLDS
A3: Release | B3: # | C3: Metric Name | D3: Category | E3: Sub-Category | F3: Description | G3: Calculation / Formula | H3: Data Source (Process) | I3: Source System / Tool | J3: Data Owner | K3: Update Frequency | L3: Unit / Format | M3: Reporting Period | N3: Current Capability (Y / N) | O3: If YES — Current Process | P3: If YES — Data Source(s) | Q3: If NO — Gap Description | R3: If NO — Process to Implement | S3: Priority to Implement | T3: Target Date | U3: Dashboard Section | V3: KPI / Measure Owner | W3: Notes / Assumptions | X3: RAG Green Threshold | Y3: RAG Amber Threshold | Z3: RAG Red Threshold | AA3: Benchmark / Target | AB3: Validated By | AC3: Date | AD3: Comments / Q's
A4: MVP | B4: 1 | C4: Active Projects | D4: Portfolio Snapshot | E4: Portfolio at a Glance | F4: Total count of nxzen (UK & India) active projects | G4: COUNT of active projects from the Dynamics Project extract | H4: Active projects in Dynamics | I4: Extract from Dynamics (link TBC) | J4: Finance | K4: Weekly | L4: Count (#) | M4: Current month | N4: Y (partial) | O4: Finance have a list of all projects | P4: Extract from Dynamics | Q4: Would need to count only active projects (e.g. remove managed svcs, etc.) | R4: Filter extract to only counts active projects | S4: High | U4: Portfolio Snapshot | V4: Syed | W4: Dormant or closed projects excluded. | X4: N/A | Y4: N/A | Z4: N/A | AA4: N/A | AB4: Syed | AC4: 46143
A5: MVP | B5: 2 | C5: Active Clients | D5: Portfolio Snapshot | E5: Portfolio at a Glance | F5: Number of distinct (UK & India) clients with at least one active project | G5: COUNT DISTINCT (Client) of active projects from the Dynamics Project extract | H5: Active projects in Dynamics | I5: Extract from Dynamics (link TBC) | J5: Finance | K5: Weekly | L5: Count (#) | M5: Current month | N5: Y (partial) | O5: Finance have a list of all projects | P5: Extract from Dynamics shows customer (Client) | Q5: Would need to count only clients with a current active project(s) (e.g. remove managed svcs, etc.) | R5: Filter extract to only counts clients with an active project(s) | S5: High | U5: Portfolio Snapshot | V5: Syed | W5: One client may have multiple projects; deduplicated count. | X5: N/A | Y5: N/A | Z5: N/A | AA5: N/A | AB5: Syed | AC5: 46143
A6: MVP | B6: 3 | C6: Overall RAG Status | D6: Portfolio Snapshot | E6: Portfolio at a Glance | F6: Overall RAG status of the portfolio | G6: If overall RAG Red %: ≥10% then Red If overall RAG Amber %:≥5%–<10% then Amber If overall RAG Green %: <5% Red or Amber, then Green | H6: PM-reported RAG per project during weekly review | I6: Acct Delivery Status Report: Milestone plan | J6: PM (reported), Portfolio Office (validate & consolidate) | K6: Weekly | L6: % (one decimal) | M6: Current week | N6: Y (partial) | O6: PMs self-report RAG per project / acct; Portfolio Office analyses each report, validates. No Portfolio / overall RAG | P6: Acct delivery weekly reports (.PPT) | Q6: Currently no overall / portfolio RAG status | R6: Need to apply portfolio / overall RAG criteria & apply for all active projects | S6: High | U6: Portfolio Snapshot | V6: Syed | W6: Overall RAG: Red: ≥10% Proj Red Overall RAG: Amber: Not Red & ≥5% Amber Overall RAG: Green: Not Red or Amber | X6: <5% Red or Amber | Y6: ≥5%–<10% | Z6: ≥10% | AA6: Green | AB6: Syed | AC6: 46143
A7: MVP | B7: 4 | C7: Overall RAG — Red % | D7: Portfolio Snapshot | E7: Portfolio at a Glance | F7: Percentage of active projects with an overall RAG status of Red. | G7: COUNT(Overall RAG = Red) / COUNT(Active Projects) × 100 | H7: PM-reported RAG per project during weekly review | I7: Acct Delivery Status Report: Milestone plan | J7: PM (reported), Portfolio Office (validate & consolidate) | K7: Weekly | L7: % (one decimal) | M7: Current week | N7: Y (partial) | O7: PMs self-report RAG per project / acct; Portfolio Office analyses each report, validates. No Portfolio / overall RAG | P7: Acct delivery weekly reports (.PPT) | Q7: Currently no overall / portfolio RAG status | R7: Need to apply portfolio / overall RAG criteria & apply for all active projects | S7: High | U7: Portfolio Snapshot | V7: Syed | W7: Overall RAG criteria: Red: ≥10% of projects are Red. | X7: <5% Red or Amber | Y7: ≥5%–<10% | Z7: ≥10% | AA7: ≤3% red | AB7: Syed | AC7: 46143 | AD7: 1. Process to gather data is there, not being followed in all instances. 2. Notes / Assumptions Red criteria is for per account, not portfolio / overall RAG.
A8: MVP | B8: 5 | C8: Overall RAG — Amber % | D8: Portfolio Snapshot | E8: Portfolio at a Glance | F8: Percentage of active projects with an overall RAG status of Amber. | G8: COUNT(Overall RAG = Amber) / COUNT(Active Projects) × 100 | H8: PM-reported RAG per project during weekly review | I8: Acct Delivery Status Report: Delivery status | J8: PM (reported), Portfolio Office (validate & consolidate) | K8: Weekly | L8: % (one decimal) | M8: Current week | N8: Y (partial) | O8: PMs self-report RAG per project / acct; Portfolio Office analyses each report, validates. No Portfolio / overall RAG | P8: Acct delivery weekly reports (.PPT) | Q8: Currently no overall / portfolio RAG status | R8: Need to apply portfolio / overall RAG criteria & apply for all active projects | S8: High | U8: Portfolio Snapshot | V8: Syed | W8: Overall RAG criteria: Amber: overall RAG is not Red & ≥5% of projects are Amber | X8: <5% Red or Amber | Y8: ≥5%–<10% | Z8: ≥10% | AA8: ≤7% amber | AB8: Syed | AC8: 46143 | AD8: 1. Process to gather data is there, not being followed in all instances.
A9: MVP | B9: 6 | C9: Overall RAG — Green % | D9: Portfolio Snapshot | E9: Portfolio at a Glance | F9: Percentage of active projects with an overall RAG status of Green. | G9: COUNT(Overall RAG = Green) / COUNT(Active Projects) × 100 | H9: PM-reported RAG per project during weekly review | I9: Acct Delivery Status Report: Delivery status | J9: PM (reported), Portfolio Office (validate & consolidate) | K9: Weekly | L9: % (one decimal) | M9: Current week | N9: Y (partial) | O9: PMs self-report RAG per project / acct; Portfolio Office analyses each report, validates. No Portfolio / overall RAG | P9: Acct delivery weekly reports (.PPT) | Q9: Currently no overall / portfolio RAG status | R9: Need to apply portfolio / overall RAG criteria & apply for all active projects | S9: High | U9: Portfolio Snapshot | V9: Syed | W9: Overall RAG criteria: Green: overall RAG is not Red or Amber | X9: <5% Red or Amber | Y9: ≥5%–<10% | Z9: ≥10% | AA9: ≥90% green | AB9: Syed | AC9: 46143 | AD9: 1. Process to gather data is there, not being followed in all instances.
A10: MVP | B10: 7 | C10: On Time % | D10: Portfolio Snapshot | E10: Delivery Indicators | F10: Measures the next due milestone. Percentage of active projects tracking on schedule (On schedule RAG: Green = no slippage). | G10: COUNT (Next due milestone RAG = Green) / COUNT (Active Projects) × 100 | H10: PM provides milestone plan and actual progress weekly | I10: Acct Delivery Status Report: Milestone plan | J10: PM (reported), Portfolio Office (validate & consolidate) | K10: Weekly | L10: % (one decimal) | M10: Current week | N10: Y (partial) | O10: PMs self-report milestones per project / acct; Portfolio Office analyses each report, validates. No Portfolio / overall % on time | P10: Acct delivery weekly reports (.PPT) | Q10: No standard milestone tracking tool or format across all PMs. Schedule data not consolidated. | R10: Define standard milestone template; PMs update weekly; Portfolio Office validates & consolidates at account review. Automate extraction via AI agent. | S10: High | T10: 01/06/2026 | U10: Portfolio Snapshot | V10: PM per project | W10: RAG: Red = project has slipped. Amber = project at risk of slippage unless action is taken. Green = no slippage & no risk of slippage. Benchmark from current wireframe: 71% on-time. | X10: ≥80% | Y10: 65–<80% | Z10: <65% | AA10: ≥80% | AB10: Syed | AC10: 46143
A11: MVP | B11: 8 | C11: Projects Behind Schedule (count) | D11: Portfolio Snapshot | E11: Delivery Indicators | F11: Measures the next due milestone. Count of active projects where schedule RAG: Red = next due milestone has slipped. | G11: COUNT(Next due milestone RAG = Red) | H11: PM provides milestone plan and actual progress weekly | I11: Acct Delivery Status Report: Milestone plan | J11: PM (reported), Portfolio Office (validate & consolidate) | K11: Weekly | L11: Count (#) | M11: Current week | N11: Y (partial) | O11: PMs self-report milestones per project / acct; Portfolio Office analyses each report, validates. No Portfolio / overall behind schedule count | P11: Acct delivery weekly reports (.PPT) | Q11: No standard milestone tracking tool or format across all PMs. Schedule data not consolidated. | R11: Define standard milestone template; PMs update weekly; Portfolio Office validates & consolidates at account review. Automate extraction via AI agent. | S11: High | T11: 01/06/2026 | U11: Portfolio Snapshot | V11: PM per project | W11: RAG: Red = project has slipped. Amber = project at risk of slippage unless action is taken. Green = no slippage & no risk of slippage. | X11: N/A | Y11: N/A | Z11: N/A | AA11: N/A | AB11: Syed | AC11: 46143
A12: REL 2 | B12: 9 | C12: On Budget % | D12: Portfolio Snapshot | E12: Delivery Indicators | F12: Percentage of active projects, where forecast cost is in line with approved budget. (Budget RAG: Green = is in line with approved budget). | G12: COUNT(Budget RAG = Green) / COUNT(Active Projects) × 100 | H12: PM and Finance provide actual vs budget cost data | I12: Finance system + PM budget tracker | J12: Finance (actuals), PM (forecast) | K12: Monthly (minimum) | L12: % (one decimal) | M12: Current month | N12: N | O12: Budget data held in Finance system but not linked to project register or dashboard. No standard budget tracker per project. | Q12: Actuals in Finance system; forecast held informally by PM. No single source. No automated consolidation. | R12: Introduce standard project budget tracker (template). Finance to share actuals monthly. PM to update forecast. Portfolio Office to consolidate. | S12: High | T12: 01/06/2026 | U12: Portfolio Snapshot | V12: PM per project | W12: RAG: Red = project is over budget. Amber = project at risk of going over budget unless action is taken. Green = not over budget & not at risk of going over. | X12: ≥80% | Y12: 65–<80% | Z12: <65% | AA12: ≥80% | AB12: Syed | AC12: 46143
A13: REL 2 | B13: 10 | C13: Projects Over Budget (count) | D13: Portfolio Snapshot | E13: Delivery Indicators | F13: Count of active projects where forecast cost exceeds approved budget. | G13: COUNT (Budget RAG = Red) | H13: PM and Finance provide actual vs budget cost data | I13: Finance system + PM budget tracker | J13: Finance (actuals), PM (forecast) | K13: Monthly | L13: Count (#) | M13: Current month | N13: N | O13: Budget data held in Finance system but not linked to project register or dashboard. No standard budget tracker per project. | Q13: Actuals in Finance system; forecast held informally by PM. No single source. No automated consolidation. | R13: Introduce standard project budget tracker (template). Finance to share actuals monthly. PM to update forecast. Portfolio Office to consolidate. | S13: High | T13: 01/06/2026 | U13: Portfolio Snapshot | V13: PM per project | W13: RAG: Red = project is over budget. Amber = project at risk of going over budget unless action is taken. Green = not over budget & not at risk of going over. | X13: N/A | Y13: N/A | Z13: N/A | AA13: N/A | AB13: Syed | AC13: 46143
A14: MVP | B14: 11 | C14: Resource Gaps Flagged | D14: Portfolio Snapshot | E14: Delivery Indicators | F14: Count of active projects with a flagged resource gap (Resource RAG = Red or Amber). | G14: COUNT(Resource RAG ∈ {Amber, Red}) | H14: PM flags resource gaps at weekly account review | I14: PM status update / resource plan | J14: PM (flagged), Portfolio Office (consolidated) | K14: Weekly | L14: Count (#) | M14: Current week | N14: Y (partial) | O14: PMs flag resource gaps verbally in account reviews. Not formally tracked or logged. | P14: Verbal account review notes | Q14: Gaps flagged informally — no structured log or consistent criteria. | R14: Add resource gap field to weekly PM status template. Log in project register. Alert Portfolio Office when flagged. | S14: Medium | T14: 01/05/2026 | U14: Portfolio Snapshot | V14: Resource Manager | W14: RAG: Red = resource issue now / will miss schedule unless action is taken. Amber = will become a resource problem unless action is taken. Green = no resource issues | X14: 0 | Y14: >0–<2 | Z14: ≥2 | AA14: 0 | AB14: Syed | AC14: 46143
A15: REL 3 | B15: 12 | C15: Client Satisfaction Score | D15: Portfolio Snapshot | E15: Delivery Indicators | F15: Percentage of clients rating project delivery ≥4/5 (or equivalent) in most recent satisfaction check. | G15: COUNT(CSAT ≥4) / COUNT(CSAT responses) × 100 | H15: Client satisfaction survey or conversation-based check with CP | I15: Survey tool or structured CP debrief | J15: TBC (a Corporate owner is required) | K15: Monthly / per milestone | L15: % (one decimal) | M15: Last 30 days or last survey round | N15: N | O15: No formal client satisfaction process or survey tool in place. | Q15: CSAT not systematically collected. CPs have informal client sentiment but no structured data. | R15: Define lightweight CSAT process (1–5 rating + comment at milestone/monthly). CP collects and logs. Portfolio Office aggregates. | S15: High | T15: 01/06/2026 | U15: Portfolio Snapshot | V15: TBC (a Corporate owner is required) | W15: Benchmark from wireframe: 69%. A Corporate owner is required for this measure so as to be independent of the sales / delivery function | X15: ≥90% | Y15: 60–<90% | Z15: <60% | AA15: ≥90% | AB15: TBC | AC15: 46143 | AD15: I think the green should be ≥90% similar measure for NPS (9 & 10 - promoters, whereas 8 (80%) would be passives, indicates our clients are indifferent to us)
A16: MVP | B16: 13 | C16: Utilisation – UK (overall) | D16: Resource & Utilisation | E16: Overall | F16: Percentage of billable & business/practice developmenthours worked against available billable & internal project capacity for UK-based resources. | G16: Billable & business/practice development (hours) logged / Available billable & internal project hours (contracted − leave) × 100 | H16: Timesheets submitted weekly by all UK resources | I16: Dynamics Timesheets BI | J16: Resource Manager / Finance | K16: Weekly | L16: % (one decimal) | M16: Current week / rolling 4-week avg | N16: Y (partial) | O16: Timesheets saved weekly. BI report can separate UK & IN users. | P16: Dynamics Timesheets | Q16: Currently report on current / past week & month not rolling 4 weeks Need to confirm the calculation with Saurabh | R16: Build automated utilisation calculation from timesheet data; surface weekly in dashboard. | S16: Medium | T16: 01/05/2026 | U16: Portfolio Snapshot | V16: Resource Manager | W16: Target 82% billable utilisation. | X16: ≥82% | Y16: 70–<82% | Z16: <70% | AA16: 82% | AB16: Syed | AC16: 46143 | AD16: Can we review the calculation in Timesheets (BI), to fit our need here
A17: MVP | B17: 14 | C17: Utilisation – India (overall) | D17: Resource & Utilisation | E17: Overall | F17: Percentage of billable & business/practice development hours worked against available billable & internal project capacity for India-based resources. | G17: Billable & business/practice development (hours) logged / Available billable & internal project hours (contracted − leave) × 100 | H17: Timesheets submitted weekly by India resources | I17: Dynamics Timesheets BI | J17: Resource Manager / India Resource Lead | K17: Weekly | L17: % (one decimal) | M17: Current week / rolling 4-week avg | N17: Y (partial) | O17: Timesheets saved weekly. BI report can separate UK & IN users. | P17: Dynamics Timesheets | Q17: Currently report on current / past week & month not rolling 4 weeks Need to confirm the calculation with Saurabh | R17: Build automated utilisation calculation from timesheet data; surface weekly in dashboard. | S17: High | T17: 01/06/2026 | U17: Portfolio Snapshot | V17: India Resource Lead | W17: Target 82% billable utilisation. | X17: ≥82% | Y17: 70–<82% | Z17: <70% | AA17: 82% | AB17: Syed | AC17: 46143 | AD17: Timesheet data entry and BI reports are one and the same for UK & India (unless something has changed) so in theory one fix will suffice for both areas (and AU/NZ when their time comes)
A18: REL 2 | B18: 15 | C18: Utilisation – by Practice (Renewables & Eng) | D18: Resource & Utilisation | E18: By Practice | F18: Percentage of billable & business/practice development utilisation for resources aligned to the Renewables & Engineering practice/sub-proposition. | G18: Billable & ibusiness/practice development hours logged (Renewables & Eng resources) / Available billable hours (same group) × 100 | H18: Timesheets submitted weekly by all UK & India resources | I18: Dynamics Timesheets BI | J18: Practice Lead / Resource Manager | K18: Weekly | L18: % (one decimal) | M18: Current week | N18: N | Q18: No practice-level tagging in timesheet or resource data. Cannot slice utilisation by practice. | R18: Tag all resources with practice/sub-proposition in resource system. Build grouping logic in dashboard. | S18: High | T18: 01/06/2026 | U18: Portfolio Snapshot | V18: Practice Lead | W18: Practices: Renewables & Eng | Data Intelligence & AI | Cyber | Apps & Dev | OT. | X18: ≥82% | Y18: 70–<82% | Z18: <70% | AA18: 82% | AB18: Syed | AC18: 46143
A19: REL 2 | B19: 16 | C19: Utilisation – by Practice (Data Intelligence & AI) | D19: Resource & Utilisation | E19: By Practice | F19: Percentage of billable & business/practice development utilisation for resources aligned to the Data Intelligence & AI practice. | G19: Billable & business/practice development hours logged (Data Intelligence & AI) / Available billable hours (same group) × 101 | H19: Timesheets submitted weekly by all UK & India resources | I19: Dynamics Timesheets BI | J19: Practice Lead / Resource Manager | K19: Weekly | L19: % (one decimal) | M19: Current week | N19: N | Q19: No practice-level tagging in timesheet or resource data. Cannot slice utilisation by practice. | R19: Tag all resources with practice/sub-proposition in resource system. Build grouping logic in dashboard. | S19: High | T19: 01/06/2026 | U19: Portfolio Snapshot | V19: Practice Lead | X19: ≥82% | Y19: 70–<82% | Z19: <70% | AA19: 82% | AB19: Syed | AC19: 46143
A20: REL 2 | B20: 17 | C20: Utilisation – by Practice (Cyber Security) | D20: Resource & Utilisation | E20: By Practice | F20: Percentage of billable & business/practice development utilisation for resources aligned to the Cyber Security practice/sub-proposition. | G20: Billable & ibusiness/practice development hours logged (Cyber Security resources) / Available billable hours (same group) × 100 | H20: Timesheets submitted weekly by all UK & India resources | I20: Dynamics Timesheets BI | J20: Practice Lead / Resource Manager | K20: Weekly | L20: % (one decimal) | M20: Current week | N20: N | Q20: No practice-level tagging in timesheet or resource data. Cannot slice utilisation by practice. | R20: Tag all resources with practice/sub-proposition in resource system. Build grouping logic in dashboard. | S20: High | T20: 01/06/2026 | U20: Portfolio Snapshot | V20: Practice Lead | W20: Practices: Renewables & Eng | Data Intelligence & AI | Cyber | Apps & Dev | OT. | X20: ≥82% | Y20: 70–<82% | Z20: <70% | AA20: 82% | AB20: Syed | AC20: 46143
A21: REL 2 | B21: 18 | C21: Utilisation – by Practice (Apps & Development) | D21: Resource & Utilisation | E21: By Practice | F21: Percentage of billable & business/practice development utilisation for resources aligned to the Aps & Development practice/sub-proposition. | G21: Billable & ibusiness/practice development hours logged (Apps & Development resources) / Available billable hours (same group) × 100 | H21: Timesheets submitted weekly by all UK & India resources | I21: Dynamics Timesheets BI | J21: Practice Lead / Resource Manager | K21: Weekly | L21: % (one decimal) | M21: Current week | N21: N | Q21: No practice-level tagging in timesheet or resource data. Cannot slice utilisation by practice. | R21: Tag all resources with practice/sub-proposition in resource system. Build grouping logic in dashboard. | S21: High | T21: 01/06/2026 | U21: Portfolio Snapshot | V21: Practice Lead | W21: Practices: Renewables & Eng | Data Intelligence & AI | Cyber | Apps & Dev | OT. | X21: ≥82% | Y21: 70–<82% | Z21: <70% | AA21: 82% | AB21: Syed | AC21: 46143
A22: REL 2 | B22: 19 | C22: Utilisation – by Practice (OT) | D22: Resource & Utilisation | E22: By Practice | F22: Percentage of billable & business/practice development utilisation for resources aligned to the OT practice/sub-proposition. | G22: Billable & ibusiness/practice development hours logged (OT resources) / Available billable hours (same group) × 100 | H22: Timesheets submitted weekly by all UK & India resources | I22: Dynamics Timesheets BI | J22: Practice Lead / Resource Manager | K22: Weekly | L22: % (one decimal) | M22: Current week | N22: N | Q22: No practice-level tagging in timesheet or resource data. Cannot slice utilisation by practice. | R22: Tag all resources with practice/sub-proposition in resource system. Build grouping logic in dashboard. | S22: High | T22: 01/06/2026 | U22: Portfolio Snapshot | V22: Practice Lead | W22: Practices: Renewables & Eng | Data Intelligence & AI | Cyber | Apps & Dev | OT. | X22: ≥82% | Y22: 70–<82% | Z22: <70% | AA22: 82% | AB22: Syed | AC22: 46143
A23: MVP | B23: 20 | C23: Unassigned Resources % | D23: Resource & Utilisation | E23: Capacity | F23: Percentage of total UK & India resource headcount currently unassigned to any active project. | G23: COUNT(Unassigned FTE excl. Corporate) / Total FTE (excl. Corporate) × 100 | H23: Timesheets submitted weekly by all UK & India resources | I23: Dynamics Timesheets BI | J23: Resource Manager | K23: Weekly | L23: % (one decimal) | M23: Current week | N23: Y | O23: Users log time and select "Type" "unassigned" | P23: Dynamics Timesheets | S23: High | T23: 01/06/2026 | U23: Portfolio Snapshot | V23: Resource Manager | W23: Benchmark: 11%. | X23: ≤10% | Y23: >10–≤20% | Z23: >20% | AA23: ≤10% | AB23: Syed | AC23: 46143
A24: MVP | B24: 21 | C24: Unbillable Resources % | D24: Resource & Utilisation | E24: Capacity | F24: Percentage of total UK & India hours logged against non-billable codes (internal, bench, training). | G24: Non-billable hours (excl. Corporate) / Total logged hours (excl. Corporate) × 100 | H24: Timesheet data — hours logged to non-billable project codes | I24: Dynamics Timesheets BI | J24: Finance / Resource Manager | K24: Weekly | L24: % (one decimal) | M24: Current week / rolling 4-week | N24: Y | O24: Users log time against "Type" & "Project" | P24: Dynamics Timesheets | S24: Medium | T24: 01/05/2026 | U24: Portfolio Snapshot | V24: Finance | W24: Benchmark: 26%. Includes bench time, internal projects, training. | X24: ≤15% | Y24: >15–25% | Z24: >25% | AA24: ≤15% | AB24: Syed | AC24: 46143
A25: MVP | B25: 22 | C25: Schedule RAG per Project | D25: Delivery Health | E25: Project Status | F25: Measures the project as a whole. Schedule performance for each active project rated Green/Amber/Red against defined criteria. | G25: Green: no slippage; Amber: risk of slippage if no action taken Red project has slipped. | H25: PM provides milestone actuals vs baseline at weekly account review | I25: Project plan (standardised template) | J25: PM | K25: Weekly | L25: RAG (G/A/R) | M25: Current week | N25: Y (partial) | Q25: Each PM uses different tools (Excel, MS Project, Jira). No baseline plan consistently maintained. | R25: Mandate standard milestone plan template. PMs update weekly. RAG auto-calculated. Portfolio Office reviews in account review. | S25: High | T25: 01/06/2026 | U25: Delivery Health | V25: PM per project | W25: RAG: Red = project has slipped. Amber = project at risk of slippage unless action is taken. Green = no slippage & no risk of slippage. | X25: ≤5% slip | Y25: >5–15% slip | Z25: >15% slip | AA25: Green | AB25: Syed | AC25: 46143
A26: REL 2 | B26: 23 | C26: Target Margin RAG per Project | D26: Delivery Health | E26: Project Status | F26: Target margin performance for each active project rated against approved budget. | G26: Green <2% variance; Amber 2–5% variance; Red >5% variance | H26: Finance actuals + PM forecast submitted monthly (minimum) or at milestone | I26: Finance system + PM budget tracker | J26: Finance (actuals), PM (forecast) | K26: Monthly | L26: RAG (G/A/R) | M26: Current month | N26: N | Q26: Actuals in Finance system; forecast held informally by PM. No single source. No automated consolidation. | R26: Introduce standard project budget tracker (template). Finance to share actuals monthly. PM to update forecast. Portfolio Office to consolidate. | S26: High | T26: 01/06/2026 | U26: Delivery Health | V26: PM per project | X26: <2% | Y26: 2–5% | Z26: >5% | AA26: Green | AB26: Sarah B | AC26: 46143
A27: MVP | B27: 24 | C27: Resource RAG per Project | D27: Delivery Health | E27: Project Status | F27: Resource health per active project. RAG: Red = resource issue now / will miss schedule unless action is taken. Amber = will become a resource problem unless action is taken. Green = no resource issues | G27: PM assessment against role/skill requirement plan vs actuals. | H27: PM assessment at weekly account review | I27: PM status update | J27: PM | K27: Weekly | L27: RAG (G/A/R) | M27: Current week | N27: Y (partial) | O27: PMs informally assess resource health. Not formally documented or logged against criteria. | P27: Verbal PM update | Q27: No formal resource requirement plan per project to compare against. | R27: Define standard resource plan template per project. PM assesses weekly against criteria. Log in project register. | S27: Medium | T27: 01/05/2026 | U27: Delivery Health | V27: PM per project | X27: No resource issues | Y27: Become resource issue unless action taken | Z27: Is a resource issue. Schedule missed if no action taken | AA27: Green | AB27: Syed | AC27: 46143
A28: REL 2 | B28: 25 | C28: Scope RAG per Project | D28: Delivery Health | E28: Project Status | F28: Scope stability per active project: Green = baseline approved and stable; Amber = changes identified not yet agreed; Red = uncontrolled scope change impacting T/C/Q. | G28: PM assessment against agreed scope baseline. | H28: PM reports scope status at account review | I28: Project scope document + change log | J28: PM | K28: Weekly | L28: RAG (G/A/R) | M28: Current week | N28: N | O28: Change log and scope baseline not maintained consistently across projects. | Q28: No standard change log or scope baseline documentation per active project. | R28: Mandate scope baseline document and change log per active project. PM updates weekly. RAG assessed against criteria. | S28: High | T28: 01/06/2026 | U28: Delivery Health | V28: PM per project | X28: Stable / approved | Y28: Change identified not yet agreed | Z28: Uncontrolled change | AA28: Green | AB28: Syed | AC28: 46143
A29: MVP | B29: 26 | C29: Open Risks per Project | D29: Delivery Health | E29: Risks & Issues | F29: Count and detail of open risks per active project, categorised by rating and status. | G29: COUNT(Risks where Status = Open), grouped by active project and severity. | H29: PM-maintained risk register updated weekly | I29: Risk register (standardised template) | J29: PM | K29: Weekly | L29: Count + detail | M29: Current week | N29: Y (partial) | O29: Risk logs exist informally per PM but no standard format and no consolidated view. | Q29: No standard risk register template or consolidated risk log. No consistent severity rating scale. | R29: Define standard risk register template with probability/impact scoring. PMs update weekly. Portfolio Office consolidates and surfaces High risks. | S29: High | T29: 01/06/2026 | U29: Delivery Health | V29: PM per project | W29: Risk Assessment Aid | X29: N/A | Y29: N/A | Z29: N/A | AA29: N/A | AB29: Syed | AC29: 46143 | AD29: Displayed in Top Risks & Issues log on dashboard.
A30: MVP | B30: 27 | C30: Open Issues per Project | D30: Delivery Health | E30: Risks & Issues | F30: Count and detail of open issues (materialised risks or blockers) per active project. | G30: COUNT(Issues where Status = Open), grouped by active project. | H30: PM-maintained issue log updated weekly | I30: Issue log (standardised template) | J30: PM | K30: Weekly | L30: Count + detail | M30: Current week | N30: Y (partial) | O30: Issues not formally tracked. Raised verbally in account reviews but not logged. | Q30: No standard issue log. Issues not differentiated from risks. | R30: Define and mandate issue log (separate from risk log). PMs update weekly. Portfolio Office consolidates. | S30: High | T30: 01/06/2026 | U30: Delivery Health | V30: PM per project | W30: Displayed in Top Risks & Issues log on dashboard. | X30: N/A | Y30: N/A | Z30: N/A | AA30: N/A | AB30: Syed | AC30: 46143
A31: REL 1 | B31: 28 | C31: Total Portfolio Value | D31: Commercial | E31: Revenue | F31: Sum of contracted value of all active projects. | G31: SUM(Contracted Value) across all active projects. | H31: Contracts signed; value entered into Zen X by Cpthen entered into Finance spreadsheets | I31: Finance system / Excel spreadsheets | J31: Finance / Client Partner | K31: On contract signature (updated monthly) | L31: £ (GBP, thousands) | M31: Cumulative active portfolio | N31: Y | O31: Existing Finance process included in the Month End pack | P31: Zen X + Finance system | S31: Medium | T31: 01/05/2026 | U31: Commercial | V31: Growth | W31: Benchmark: £4.2M. | X31: N/A | Y31: N/A | Z31: N/A | AA31: N/A | AB31: Sarah B | AC31: 46143
A32: REL 1 | B32: 29 | C32: Revenue Recognised MTD | D32: Commercial | E32: Revenue | F32: Revenue formally recognised in the current month to date, per accounting policy. | G32: SUM(Revenue Recognised) where recognition date in current calendar month. | H32: Finance team applies revenue recognition and updates monthly | I32: Finance / Accounting system | J32: Finance | K32: Monthly | L32: £ (GBP, thousands) | M32: Month to date | N32: Y | O32: Finance recognises revenue monthly per project. Data exists but not surfaced in dashboard. | P32: Finance accounting system & spreadsheets | S32: Medium | U32: Commercial | V32: Growth | W32: Finance | X32: Benchmark: £1.1M MTD. Show vs plan variance. | Y32: N/A | Z32: N/A | AA32: N/A | AB32: Sarah B | AC32: 46143
A33: REL 1 | B33: 30 | C33: Revenue vs Plan Variance | D33: Commercial | E33: Revenue | F33: Difference between actual revenue recognised MTD and planned revenue for the month. | G33: Revenue Recognised MTD − Revenue Plan MTD. Show as £ and %. | H33: Finance actuals vs revenue plan (set at project kick-off or annual plan) | I33: Finance system + revenue plan | J33: Finance | K33: Monthly (ideally weekly) | L33: £ and % | M33: Month to date | N33: Y | O33: Existing Finance process included in the Month End pack | P33: Finance accounting system & spreadsheets | R33: Finance to produce monthly revenue plan at project level. Portfolio Office consolidates. Compare to actuals monthly. | S33: High | T33: 01/06/2026 | U33: Commercial | V33: Finance | W33: Benchmark: ▲£140k vs plan. | X33: N/A | Y33: N/A | Z33: N/A | AA33: N/A | AB33: Sarah B | AC33: 46143
A34: REL 1 | B34: 31 | C34: Average Project Margin % | D34: Commercial | E34: Margin | F34: Average gross margin across all active projects (revenue minus direct delivery cost). | G34: AVERAGE(Project Margin %) where Margin = (Revenue − Direct Costs) / Revenue × 100. | H34: Finance calculates margin per project from timesheet costs + expenses vs recognised revenue | I34: Finance system | J34: Finance | K34: Monthly | L34: % (one decimal) | M34: Current month | N34: Y | O34: Existing Finance process included in the Month End pack | P34: Finance accounting system & spreadsheets | R34: Finance to produce per-project margin statement monthly. Portfolio Office aggregates. Dashboard shows average and per-project. | S34: High | T34: 01/06/2026 | U34: Commercial | V34: Growth | W34: Target: 35%. Benchmark: 31%. | X34: ≥35% | Y34: 28–<35% | Z34: <28% | AA34: ≥35% | AB34: Sarah B | AC34: 46143
A35: MVP | B35: 32 | C35: Billable Utilisation % | D35: Commercial | E35: Margin | F35: Percentage of total logged hours that are billable to a client — commercial lens on utilisation. | G35: Billable hours / Total hours logged (excl. Corporate) × 100 (all resources, UK + India). | H35: Timesheet data — hours logged to billable project codes | I35: Dynamics Timesheets BI | J35: Finance / Resource Manager | K35: Weekly | L35: % (one decimal) | M35: Current week / rolling 4-week | N35: Y (partial) | O35: Timesheets saved weekly. BI report can separate UK & IN users. | P35: Dynamics Timesheets | S35: High | U35: Commercial | V35: Growth | W35: Finance. Benchmark 78% | X35: ≥82% | Y35: <82-70% | Z35: <70% | AA35: ≥82% | AB35: Syed | AC35: 46143
A36: REL 2 | B36: 33 | C36: Win Rate (6-month rolling) | D36: Commercial | E36: Pipeline | F36: Percentage of pitched opportunities won in the rolling 6-month window. | G36: COUNT(Opportunities Won) / COUNT(Opportunities Pitched) × 100 over rolling 6 months. | H36: CPs log pitches and outcomes in Zen X | I36: Zen X | J36: Client Partner / Growth team (Mike Farrell) | K36: Monthly | L36: % (one decimal) | M36: Rolling 6 months | N36: N | O36: Win/loss data not consistently logged in Zen X. Tracked informally by CPs. | Q36: Pitches and outcomes not systematically recorded. No Zen X discipline enforced. | R36: Mandate CP updates Zen X at each stage: pitched, won, lost. Define 'pitched' (formal proposal submitted). Portfolio Office extracts monthly. | S36: High | T36: 01/06/2026 | U36: Commercial | V36: Client Partner | W36: Benchmark: 44% (5 won of 11 pitched). | X36: ≥50% | Y36: 35–<50% | Z36: <35% | AA36: ≥50% | AB36: Mike | AC36: 46143
A37: REL 2 | B37: 34 | C37: Pipeline Value | D37: Commercial | E37: Pipeline | F37: Total value of opportunities currently in pipeline from Prospect to Negotiation stage. | G37: SUM(Opportunity Value) where Stage ∈ {Prospect, Qualified, Proposal, Negotiation}. | H37: CPs maintain pipeline in Zen X | I37: Zen X | J37: Client Partner / Growth team (Mike Farrell) | K37: Weekly | L37: £ (GBP, thousands) | M37: Current snapshot | N37: N | O37: Zen X not consistently used by all CPs. Pipeline values not reliably maintained. | Q37: Zen X hygiene is inconsistent. Pipeline value not a reliable source of truth. | R37: Enforce Zen X pipeline hygiene standard. Weekly CP pipeline review. Portfolio Office extracts pipeline value each Friday. | S37: High | T37: 01/06/2026 | U37: Commercial | V37: Client Partner | W37: Benchmark: £3.35M. Scope: Prospect to Negotiation. | X37: N/A | Y37: N/A | Z37: N/A | AA37: N/A | AB37: Mike | AC37: 46143
A38: REL 2 | B38: 35 | C38: Repeat Business Rate % | D38: Commercial | E38: Pipeline | F38: Percentage of revenue (or active projects) in the current period derived from existing clients (re-contracted or extended). | G38: Revenue (or active projects) from existing clients (renewed/extended) / Total Revenue × 100. | H38: CP identifies new vs repeat at project initiation. Finance validates against client history. | I38: Zen X + Finance | J38: Client Partner | K38: Monthly | L38: % (one decimal) | M38: Rolling 12 months or current period | N38: N | O38: Repeat vs new business not formally categorised in Zen X or Finance. | Q38: No field in Zen X or project register to flag new vs repeat client engagement. | R38: Add New vs Repeat flag to project register and Zen X. CP confirms at kick-off. Finance validates. | S38: Medium | T38: 46174 | U38: Commercial | V38: Client Partner | W38: Target: 60%. Benchmark: 68%. | X38: ≥60% | Y38: 50–<60% | Z38: <50% | AA38: ≥60% | AB38: Mike | AC38: 46143
A39: REL 2 | B39: 36 | C39: Average Days to Contract | D39: Commercial | E39: Pipeline | F39: Average number of calendar days from opportunity creation/bid submission to signed contract. | G39: AVERAGE(Contract Signed Date − Opportunity Created/Bid Submitted Date) across deals closed in period. | H39: CPs log opportunity creation and contract dates in Zen X | I39: Zen X | J39: Client Partner / Legal | K39: Monthly | L39: Days (whole number .5 or > rolled up) | M39: Rolling 3-month average | N39: N | O39: Contract dates not consistently logged in Zen X. Legal/procurement cycle not tracked. | Q39: No systematic tracking of bid-to-contract timeline. | R39: Log bid submission date and contract signed date in Zen X for all opportunities. Calculate automatically. | S39: Medium | T39: 46174 | U39: Commercial | V39: Client Partner | W39: Target: 20 days. Benchmark: 23 days. | X39: ≤20 days | Y39: >20–30 days | Z39: >30 days | AA39: ≤20 days | AB39: Mike | AC39: 46143
A40: REL 3 | B40: 37 | C40: Planned vs Actual Invoicing | D40: Commercial | E40: Invoicing | F40: Variance between the invoices planned to be raised in the period and the invoices actually raised. Measures billing discipline and cash flow predictability. | G40: Planned Invoice Value (period) − Actual Invoice Value (period). Express as £ variance and % variance: (Actual − Plan) / Plan × 100. Report at project level and portfolio total. | H40: Invoice schedule set at active project kick-off by CP/Finance. Actuals pulled from Finance/accounting system after month-end close. | I40: Finance / Accounting system (e.g. Xero, SAP, NetSuite) + Invoice schedule (project register or Finance tracker) | J40: Finance | K40: Monthly | L40: £ (GBP) and % variance — shown per project and portfolio total | M40: Current month / rolling quarter | N40: N | Q40: No invoice schedule is formally documented at project level. Invoicing is tracked in the Finance system but not compared against a planned schedule. No consolidated portfolio-level invoicing view exists. | R40: 1. Mandate CP/Finance to document an invoice schedule (date, milestone trigger, expected value) at active project kick-off. 2. Finance records actuals in the same tracker post-invoice. 3. Portfolio Office consolidates monthly. 4. Surface planned vs actual in dashboard with RAG: Green ≤±5%, Amber 6–15%, Red >15% or invoice missed entirely. | S40: High | T40: 01/06/2026 | U40: Commercial | V40: Finance | W40: Distinct from Revenue Recognised (metric #26/#27) — invoicing is a cash/billing event; revenue recognition follows accounting policy and may differ in timing. Both metrics are needed. A missed invoice does not equal unrecognised revenue but does signal cash flow and delivery milestone risk. | X40: ≤±5% variance | Y40: >5–15% variance or 1 invoice delayed | Z40: >15% variance or invoice missed entirely | AA40: 0% variance (invoice on time, full value) | AB40: Sarah B | AC40: 46143
...

Sheet Capability Summary
A1: Capability Assessment Summary | nxzen Portfolio Office | DRAFT May 2026
A3: # | B3: Metric Name | C3: Category | D3: Capability (Y / N / Partial) | E3: If YES — Current Process / Source | F3: If NO — Gap & Process to Implement | G3: Priority
A4: ='Metric Catalogue'!B4 -> 1 | B4: ='Metric Catalogue'!C4 -> Active Projects | C4: ='Metric Catalogue'!D4 -> Portfolio Snapshot | D4: ='Metric Catalogue'!N4 -> Y (partial) | E4: ='Metric Catalogue'!O4 &" "& 'Metric Catalogue'!P4 -> Finance have a list of all projects Extract from Dynamics | F4: ='Metric Catalogue'!Q4 &" "& 'Metric Catalogue'!R4 -> Would need to count only active projects (e.g. remove managed svcs, etc.) Filter extract to only counts active projects | G4: ='Metric Catalogue'!S4 -> High
A5: ='Metric Catalogue'!B5 -> 2 | B5: ='Metric Catalogue'!C5 -> Active Clients | C5: ='Metric Catalogue'!D5 -> Portfolio Snapshot | D5: ='Metric Catalogue'!N5 -> Y (partial) | E5: ='Metric Catalogue'!O5 &" "& 'Metric Catalogue'!P5 -> Finance have a list of all projects Extract from Dynamics shows customer (Client) | F5: ='Metric Catalogue'!Q5 &" "& 'Metric Catalogue'!R5 -> Would need to count only clients with a current active project(s) (e.g. remove managed svcs, etc.) Filter extract to only counts clients with an active project(s) | G5: ='Metric Catalogue'!S5 -> High
A6: ='Metric Catalogue'!B6 -> 3 | B6: ='Metric Catalogue'!C6 -> Overall RAG Status | C6: ='Metric Catalogue'!D6 -> Portfolio Snapshot | D6: ='Metric Catalogue'!N6 -> Y (partial) | E6: ='Metric Catalogue'!O6 &" "& 'Metric Catalogue'!P6 -> PMs self-report RAG per project / acct; Portfolio Office analyses each report, validates. No Portfolio / overall RAG Acct delivery weekly reports (.PPT) | F6: ='Metric Catalogue'!Q6 &" "& 'Metric Catalogue'!R6 -> Currently no overall / portfolio RAG status Need to apply portfolio / overall RAG criteria & apply for all active projects | G6: ='Metric Catalogue'!S6 -> High
A7: ='Metric Catalogue'!B7 -> 4 | B7: ='Metric Catalogue'!C7 -> Overall RAG — Red % | C7: ='Metric Catalogue'!D7 -> Portfolio Snapshot | D7: ='Metric Catalogue'!N7 -> Y (partial) | E7: ='Metric Catalogue'!O7 &" "& 'Metric Catalogue'!P7 -> PMs self-report RAG per project / acct; Portfolio Office analyses each report, validates. No Portfolio / overall RAG Acct delivery weekly reports (.PPT) | F7: ='Metric Catalogue'!Q7 &" "& 'Metric Catalogue'!R7 -> Currently no overall / portfolio RAG status Need to apply portfolio / overall RAG criteria & apply for all active projects | G7: ='Metric Catalogue'!S7 -> High
A8: ='Metric Catalogue'!B8 -> 5 | B8: ='Metric Catalogue'!C8 -> Overall RAG — Amber % | C8: ='Metric Catalogue'!D8 -> Portfolio Snapshot | D8: ='Metric Catalogue'!N8 -> Y (partial) | E8: ='Metric Catalogue'!O8 &" "& 'Metric Catalogue'!P8 -> PMs self-report RAG per project / acct; Portfolio Office analyses each report, validates. No Portfolio / overall RAG Acct delivery weekly reports (.PPT) | F8: ='Metric Catalogue'!Q8 &" "& 'Metric Catalogue'!R8 -> Currently no overall / portfolio RAG status Need to apply portfolio / overall RAG criteria & apply for all active projects | G8: ='Metric Catalogue'!S8 -> High
A9: ='Metric Catalogue'!B9 -> 6 | B9: ='Metric Catalogue'!C9 -> Overall RAG — Green % | C9: ='Metric Catalogue'!D9 -> Portfolio Snapshot | D9: ='Metric Catalogue'!N9 -> Y (partial) | E9: ='Metric Catalogue'!O9 &" "& 'Metric Catalogue'!P9 -> PMs self-report RAG per project / acct; Portfolio Office analyses each report, validates. No Portfolio / overall RAG Acct delivery weekly reports (.PPT) | F9: ='Metric Catalogue'!Q9 &" "& 'Metric Catalogue'!R9 -> Currently no overall / portfolio RAG status Need to apply portfolio / overall RAG criteria & apply for all active projects | G9: ='Metric Catalogue'!S9 -> High
A10: ='Metric Catalogue'!B10 -> 7 | B10: ='Metric Catalogue'!C10 -> On Time % | C10: ='Metric Catalogue'!D10 -> Portfolio Snapshot | D10: ='Metric Catalogue'!N10 -> Y (partial) | E10: ='Metric Catalogue'!O10 &" "& 'Metric Catalogue'!P10 -> PMs self-report milestones per project / acct; Portfolio Office analyses each report, validates. No Portfolio / overall % on time Acct delivery weekly reports (.PPT) | F10: ='Metric Catalogue'!Q10 &" "& 'Metric Catalogue'!R10 -> No standard milestone tracking tool or format across all PMs. Schedule data not consolidated. Define standard milestone template; PMs update weekly; Portfolio Office validates & consolidates at account review. Automate extraction via AI agent. | G10: ='Metric Catalogue'!S10 -> High
A11: ='Metric Catalogue'!B11 -> 8 | B11: ='Metric Catalogue'!C11 -> Projects Behind Schedule (count) | C11: ='Metric Catalogue'!D11 -> Portfolio Snapshot | D11: ='Metric Catalogue'!N11 -> Y (partial) | E11: ='Metric Catalogue'!O11 &" "& 'Metric Catalogue'!P11 -> PMs self-report milestones per project / acct; Portfolio Office analyses each report, validates. No Portfolio / overall behind schedule count Acct delivery weekly reports (.PPT) | F11: ='Metric Catalogue'!Q11 &" "& 'Metric Catalogue'!R11 -> No standard milestone tracking tool or format across all PMs. Schedule data not consolidated. Define standard milestone template; PMs update weekly; Portfolio Office validates & consolidates at account review. Automate extraction via AI agent. | G11: ='Metric Catalogue'!S11 -> High
A12: ='Metric Catalogue'!B12 -> 9 | B12: ='Metric Catalogue'!C12 -> On Budget % | C12: ='Metric Catalogue'!D12 -> Portfolio Snapshot | D12: ='Metric Catalogue'!N12 -> N | E12: ='Metric Catalogue'!O12 &" "& 'Metric Catalogue'!P12 -> Budget data held in Finance system but not linked to project register or dashboard. No standard budget tracker per project. | F12: ='Metric Catalogue'!Q12 &" "& 'Metric Catalogue'!R12 -> Actuals in Finance system; forecast held informally by PM. No single source. No automated consolidation. Introduce standard project budget tracker (template). Finance to share actuals monthly. PM to update forecast. Portfolio Office to consolidate. | G12: ='Metric Catalogue'!S12 -> High
A13: ='Metric Catalogue'!B13 -> 10 | B13: ='Metric Catalogue'!C13 -> Projects Over Budget (count) | C13: ='Metric Catalogue'!D13 -> Portfolio Snapshot | D13: ='Metric Catalogue'!N13 -> N | E13: ='Metric Catalogue'!O13 &" "& 'Metric Catalogue'!P13 -> Budget data held in Finance system but not linked to project register or dashboard. No standard budget tracker per project. | F13: ='Metric Catalogue'!Q13 &" "& 'Metric Catalogue'!R13 -> Actuals in Finance system; forecast held informally by PM. No single source. No automated consolidation. Introduce standard project budget tracker (template). Finance to share actuals monthly. PM to update forecast. Portfolio Office to consolidate. | G13: ='Metric Catalogue'!S13 -> High
A14: ='Metric Catalogue'!B14 -> 11 | B14: ='Metric Catalogue'!C14 -> Resource Gaps Flagged | C14: ='Metric Catalogue'!D14 -> Portfolio Snapshot | D14: ='Metric Catalogue'!N14 -> Y (partial) | E14: ='Metric Catalogue'!O14 &" "& 'Metric Catalogue'!P14 -> PMs flag resource gaps verbally in account reviews. Not formally tracked or logged. Verbal account review notes | F14: ='Metric Catalogue'!Q14 &" "& 'Metric Catalogue'!R14 -> Gaps flagged informally — no structured log or consistent criteria. Add resource gap field to weekly PM status template. Log in project register. Alert Portfolio Office when flagged. | G14: ='Metric Catalogue'!S14 -> Medium
A15: ='Metric Catalogue'!B15 -> 12 | B15: ='Metric Catalogue'!C15 -> Client Satisfaction Score | C15: ='Metric Catalogue'!D15 -> Portfolio Snapshot | D15: ='Metric Catalogue'!N15 -> N | E15: ='Metric Catalogue'!O15 &" "& 'Metric Catalogue'!P15 -> No formal client satisfaction process or survey tool in place. | F15: ='Metric Catalogue'!Q15 &" "& 'Metric Catalogue'!R15 -> CSAT not systematically collected. CPs have informal client sentiment but no structured data. Define lightweight CSAT process (1–5 rating + comment at milestone/monthly). CP collects and logs. Portfolio Office aggregates. | G15: ='Metric Catalogue'!S15 -> High
... A44: ='Metric Catalogue'!B44 -> 41 | B44: ='Metric Catalogue'!C44 -> Deals > 4 months in the pipeline | C44: ='Metric Catalogue'!D44 -> Commercial | D44: ='Metric Catalogue'!N44 -> N | E44: ='Metric Catalogue'!O44 &" "& 'Metric Catalogue'!P44 -> Zn X not consistently used by all CPs. Pipeline values not reliably maintained. | F44: ='Metric Catalogue'!Q44 &" "& 'Metric Catalogue'!R44 -> Zen X hygiene is inconsistent. Pipeline value not a reliable source of truth. Enforce Zen X pipeline hygiene standard. Weekly CP pipeline review. Portfolio Office extracts pipeline value each Friday. | G44: ='Metric Catalogue'!S44 -> Medium
A46: Y | B46: 8 | C46: =B46/B49 -> 0.19512195
A47: N | B47: 17 | C47: =B47/B50 -> 0.41463415
A48: Y (partial) | B48: 16 | C48: =B48/B49 -> 0.3902439
A49: Total | B49: =SUM(B43:B48) -> 41
A50: Check | B50: =COUNTA(A4:A44) -> 41

Sheet Glossary & Guide
A1: Glossary & Column Guide | nxzen Portfolio Office Metric Catalogue
A3: COLUMN DEFINITIONS
A4: Metric Name | B4: The name of the metric as it appears on the Portfolio Dashboard.
A5: Category | B5: Top-level grouping: Portfolio Snapshot | Resource & Utilisation | Delivery Health | Commercial.
A6: Sub-Category | B6: Second-level grouping within the category.
A7: Description | B7: Plain-English explanation of what the metric measures and why it matters.
A8: Calculation / Formula | B8: Precise formula or calculation logic. References specific data fields.
A9: Data Source (Process) | B9: The business process or activity that generates the underlying data.
A10: Source System / Tool | B10: The technology, system, or file where the data lives or will live.
A11: Data Owner | B11: The role or team responsible for providing accurate data for this metric.
A12: Update Frequency | B12: How often the metric should be refreshed (Weekly / Monthly / On event).
A13: Unit / Format | B13: How the metric is expressed: count, %, £, days, RAG, etc.
A14: Reporting Period | B14: The time window the metric covers (e.g., current week, MTD, rolling 6 months).
A15: Current Capability (Y/N) | B15: Y = data and process exist to report today. Y (partial) = data exists but incomplete or manual. N = capability does not exist.
... A26: Benchmark / Target | B26: The target or aspirational value for this metric, or a benchmark from the wireframe.
A29: KEY TERMS
A30: RAG Status | B30: Red / Amber / Green health indicator. Criteria defined per metric and in the dashboard design document.
A31: Managed Services | B31: Excluded from portfolio scope for this dashboard. Tracked separately.
A32: Portfolio Office | B32: Laura Hargrave (owner). Responsible for consolidating data, maintaining this catalogue, and producing the weekly dashboard.
A33: Account Review | B33: Weekly structured conversation between PM/CP and Portfolio Office to capture project status data.
A34: PM | B34: Project Manager — responsible for day-to-day delivery data (schedule, risk, resource, budget).
A35: CP | B35: Client Partner — responsible for commercial and client relationship data.
A36: nxzen UK | B36: Scope of this dashboard. India resources included in utilisation metrics but India projects excluded unless delivered jointly.
A37: Billable Utilisation | B37: Hours charged to a client engagement / total contracted hours available. Excludes leave and internal time.
A38: Pipeline | B38: Opportunities tracked in CRM from Prospect stage through to Negotiation. Excludes Won/Lost/On Hold.
A39: Revenue Recognised | B39: Revenue formally recognised under the company's accounting policy. Not invoiced or received — recognised.

Sheet Suggested Additions
A1: Suggested Additional Metrics & Fields | For Discussion
A3: Metric / Field | B3: Rationale / Why It Matters | C3: Priority
A4: Days Since Last Client Update | B4: Flags projects where the CP has not logged a client interaction recently. Early warning of relationship drift. Helps Portfolio Office prompt CPs proactively. | C4: High
A5: Forecast Completion Date vs Baseline | B5: For each project: original end date vs current forecast end date. Quantifies schedule drift more precisely than RAG alone. | C5: High
A6: Revenue at Risk (£) | B6: Value of active project revenue at risk based on Red/Amber-rated projects. Aggregated commercial exposure view for leadership. | C6: High
A7: Gross Margin £ per Project | B7: Absolute margin value (not just %) allows leadership to prioritise by commercial impact, not just percentage. | C7: High
A8: Open High Risks | B8: Draw attention to any risks classed as High or Very High. | C8: Medium
A9: Staff Sentiment / Wellbeing Flag | B9: Simple weekly pulse (Green/Amber/Red) per project team flagged by PM. Early indicator of delivery risk from people fatigue or conflict. | C9: Medium
A10: Quality RAG per Project | B10: Measure how we performed at each project stage / gate (standards yet to be defined and agreed. Green = all gate criteria met, Amber = ≤2 minor fails v gate criteria, Red = 1 or more major fails or >2 minors v gate criteria) | C10: Medium
A11: Days in Current Phase | B11: How long each project has been in its current phase (Discovery, Design, Build etc). Flags stalled projects before they become Red. | C11: Medium
A12: Change Requests Raised (count) | B12: Number of formal change requests raised per project per period. Proxy for scope stability and client behaviour. | C12: Medium
A13: Invoice Outstanding > 30 Days (£) | B13: Value of invoices unpaid beyond terms. Finance health indicator; also flags client relationship risk. | C13: Medium
A14: Contractor vs Permanent Split (%) | B14: Proportion of delivery resource that is contractor vs permanent. Impacts margin and risk profile. | C14: Medium
... A20: Lessons Learned Captured (Y/N) | B20: Flag per completed project whether a lessons learned exercise was conducted and documented. Drives continuous improvement. | C20: Low

Sheet Lists
A1: MVP
A2: REL 1
A3: REL 2
A4: REL 3
A5: TBC

Sheet Deleted Metrics
B1: nxzen Portfolio Office | Metric Definition Catalogue | DRAFT — April 2026
B2: METRIC IDENTITY | F2: DEFINITION | I2: DATA & GOVERNANCE | N2: CAPABILITY ASSESSMENT | U2: DASHBOARD | X2: THRESHOLDS
A3: Release | B3: # | C3: Metric Name | D3: Category | E3: Sub-Category | F3: Description | G3: Calculation / Formula | H3: Data Source (Process) | I3: Source System / Tool | J3: Data Owner | K3: Update Frequency | L3: Unit / Format | M3: Reporting Period | N3: Current Capability (Y / N) | O3: If YES — Current Process | P3: If YES — Data Source(s) | Q3: If NO — Gap Description | R3: If NO — Process to Implement | S3: Priority to Implement | T3: Target Date | U3: Dashboard Section | V3: KPI / Measure Owner | W3: Notes / Assumptions | X3: RAG Green Threshold | Y3: RAG Amber Threshold | Z3: RAG Red Threshold | AA3: Benchmark / Target | AB3: Validated By | AC3: Date | AD3: Comments / Q's
B4: 11 | C4: Open High Risks (count) | D4: Portfolio Snapshot | E4: Delivery Indicators | F4: Count of open high or very high risks across all active projects. | G4: COUNT (Risk Status = Open & high or very high) | H4: PM-maintained risk log updated at weekly account review | I4: Risk log (Excel / PPM) | J4: PM (owner), Portfolio Office (consolidated) | K4: Weekly | L4: Count (#) | M4: Current week | N4: N | O4: Risk logs exist informally per PM but no standard format and no consolidated view. | Q4: No standard risk register template or consolidated risk log. No consistent severity rating scale. | R4: Define standard risk register template with probability/impact scoring. PMs update weekly. Portfolio Office consolidates and surfaces High risks. | S4: High | T4: 01/06/2026 | U4: Portfolio Snapshot / Delivery Health | V4: PM per project | W4: See nxzen group risk register for thresholds / ratings. | X4: 0 | Y4: 1–2 | Z4: ≥2 | AA4: 0 | AB4: Syed | AC4: 46143
B5: 35 | C5: Budget Variance % per Project | D5: Commercial | E5: Budget | F5: Variance between forecast total cost and approved budget for each active project. | G5: (Forecast Cost − Approved Budget) / Approved Budget × 100. | H5: PM provides cost forecast; Finance provides actuals | I5: Finance system + PM budget tracker | J5: Finance (actuals), PM (forecast) | K5: Monthly | L5: % (one decimal) | M5: Current month forecast vs baseline | N5: N | O5: Budget data held in Finance system but not linked to project register or dashboard. No standard budget tracker per project. | Q5: Actuals in Finance system; forecast held informally by PM. No single source. No automated consolidation. | R5: Introduce standard project budget tracker (template). Finance to share actuals monthly. PM to update forecast. Portfolio Office to consolidate. | S5: High | T5: 01/06/2026 | U5: Commercial | V5: Finance | W5: Displayed as bar chart in dashboard. Green ±5%, Amber >5–15%, Red >15%. | X5: ±5% | Y5: >5–15% | Z5: >15% | AA5: ±5% | AB5: Sarah B | AC5: N/A | AD5: Reviewed with Sarah B on 29/04/26. Data required for this measure is already available in report 21 Target Margin RAG per project.
